2022-02-17 13:02:08,388 -  nornir.core -     INFO -        run() - Running task 'Backup Device configurations' with args {'path': './data/configs'} on 1 hosts
2022-02-17 13:02:08,390 - nornir.core.task -    ERROR -      start() - Host 'host1': task 'napalm_get' failed with traceback:
Traceback (most recent call last):
  File "C:\Users\Admin\AppData\Roaming\Python\Python310\site-packages\nornir\core\task.py", line 99, in start
    r = self.task(self, **self.params)
  File "C:\Users\Admin\AppData\Roaming\Python\Python310\site-packages\nornir_napalm\plugins\tasks\napalm_get.py", line 32, in napalm_get
    device = task.host.get_connection(CONNECTION_NAME, task.nornir.config)
  File "C:\Users\Admin\AppData\Roaming\Python\Python310\site-packages\nornir\core\inventory.py", line 494, in get_connection
    self.open_connection(
  File "C:\Users\Admin\AppData\Roaming\Python\Python310\site-packages\nornir\core\inventory.py", line 546, in open_connection
    conn_obj.open(
  File "C:\Users\Admin\AppData\Roaming\Python\Python310\site-packages\nornir_napalm\plugins\connections\__init__.py", line 55, in open
    network_driver = get_network_driver(platform)
  File "C:\Users\Admin\AppData\Roaming\Python\Python310\site-packages\napalm\base\__init__.py", line 68, in get_network_driver
    raise ModuleImportError("Please provide a valid driver name.")
napalm.base.exceptions.ModuleImportError: Please provide a valid driver name.

2022-02-17 13:02:08,403 - nornir.core.task -    ERROR -      start() - Host 'host1': task 'Backup Device configurations' failed with traceback:
Traceback (most recent call last):
  File "C:\Users\Admin\AppData\Roaming\Python\Python310\site-packages\nornir\core\task.py", line 99, in start
    r = self.task(self, **self.params)
  File "c:\Users\Admin\Documents\Code\Nornir\nornir\nornir_test.py", line 16, in backup_config
    device_config = task.run(task=napalm_get, getters=["config"])
  File "C:\Users\Admin\AppData\Roaming\Python\Python310\site-packages\nornir\core\task.py", line 174, in run
    raise NornirSubTaskError(task=run_task, result=r)
nornir.core.exceptions.NornirSubTaskError: Subtask: napalm_get (failed)


2022-02-17 13:04:35,094 -  nornir.core -     INFO -        run() - Running task 'Backup Device configurations' with args {'path': './data/configs'} on 1 hosts
2022-02-17 13:04:35,095 - nornir.core.task -    ERROR -      start() - Host 'host1': task 'napalm_get' failed with traceback:
Traceback (most recent call last):
  File "C:\Users\Admin\AppData\Roaming\Python\Python310\site-packages\nornir\core\task.py", line 99, in start
    r = self.task(self, **self.params)
  File "C:\Users\Admin\AppData\Roaming\Python\Python310\site-packages\nornir_napalm\plugins\tasks\napalm_get.py", line 32, in napalm_get
    device = task.host.get_connection(CONNECTION_NAME, task.nornir.config)
  File "C:\Users\Admin\AppData\Roaming\Python\Python310\site-packages\nornir\core\inventory.py", line 494, in get_connection
    self.open_connection(
  File "C:\Users\Admin\AppData\Roaming\Python\Python310\site-packages\nornir\core\inventory.py", line 546, in open_connection
    conn_obj.open(
  File "C:\Users\Admin\AppData\Roaming\Python\Python310\site-packages\nornir_napalm\plugins\connections\__init__.py", line 55, in open
    network_driver = get_network_driver(platform)
  File "C:\Users\Admin\AppData\Roaming\Python\Python310\site-packages\napalm\base\__init__.py", line 68, in get_network_driver
    raise ModuleImportError("Please provide a valid driver name.")
napalm.base.exceptions.ModuleImportError: Please provide a valid driver name.

2022-02-17 13:04:35,095 - nornir.core.task -    ERROR -      start() - Host 'host1': task 'Backup Device configurations' failed with traceback:
Traceback (most recent call last):
  File "C:\Users\Admin\AppData\Roaming\Python\Python310\site-packages\nornir\core\task.py", line 99, in start
    r = self.task(self, **self.params)
  File "c:\Users\Admin\Documents\Code\Nornir\nornir\nornir_test.py", line 16, in backup_config
    device_config = task.run(task=napalm_get, getters=["get_config"])
  File "C:\Users\Admin\AppData\Roaming\Python\Python310\site-packages\nornir\core\task.py", line 174, in run
    raise NornirSubTaskError(task=run_task, result=r)
nornir.core.exceptions.NornirSubTaskError: Subtask: napalm_get (failed)


2022-02-17 13:06:25,798 -  nornir.core -     INFO -        run() - Running task 'Backup Device configurations' with args {'path': './data/configs'} on 1 hosts
2022-02-17 13:06:25,800 - nornir.core.task -    ERROR -      start() - Host 'host1': task 'napalm_get' failed with traceback:
Traceback (most recent call last):
  File "C:\Users\Admin\AppData\Roaming\Python\Python310\site-packages\nornir\core\task.py", line 99, in start
    r = self.task(self, **self.params)
  File "C:\Users\Admin\AppData\Roaming\Python\Python310\site-packages\nornir_napalm\plugins\tasks\napalm_get.py", line 32, in napalm_get
    device = task.host.get_connection(CONNECTION_NAME, task.nornir.config)
  File "C:\Users\Admin\AppData\Roaming\Python\Python310\site-packages\nornir\core\inventory.py", line 494, in get_connection
    self.open_connection(
  File "C:\Users\Admin\AppData\Roaming\Python\Python310\site-packages\nornir\core\inventory.py", line 546, in open_connection
    conn_obj.open(
  File "C:\Users\Admin\AppData\Roaming\Python\Python310\site-packages\nornir_napalm\plugins\connections\__init__.py", line 55, in open
    network_driver = get_network_driver(platform)
  File "C:\Users\Admin\AppData\Roaming\Python\Python310\site-packages\napalm\base\__init__.py", line 68, in get_network_driver
    raise ModuleImportError("Please provide a valid driver name.")
napalm.base.exceptions.ModuleImportError: Please provide a valid driver name.

2022-02-17 13:06:25,800 - nornir.core.task -    ERROR -      start() - Host 'host1': task 'Backup Device configurations' failed with traceback:
Traceback (most recent call last):
  File "C:\Users\Admin\AppData\Roaming\Python\Python310\site-packages\nornir\core\task.py", line 99, in start
    r = self.task(self, **self.params)
  File "c:\Users\Admin\Documents\Code\Nornir\nornir\nornir_test.py", line 16, in backup_config
    device_config = task.run(task=napalm_get, getters=["get_config"])
  File "C:\Users\Admin\AppData\Roaming\Python\Python310\site-packages\nornir\core\task.py", line 174, in run
    raise NornirSubTaskError(task=run_task, result=r)
nornir.core.exceptions.NornirSubTaskError: Subtask: napalm_get (failed)


2022-02-17 13:07:56,562 -  nornir.core -     INFO -        run() - Running task 'Backup Device configurations' with args {'path': './data/configs'} on 1 hosts
2022-02-17 13:07:56,562 - nornir.core.task -    ERROR -      start() - Host 'host1': task 'napalm_get' failed with traceback:
Traceback (most recent call last):
  File "C:\Users\Admin\AppData\Roaming\Python\Python310\site-packages\nornir\core\task.py", line 99, in start
    r = self.task(self, **self.params)
  File "C:\Users\Admin\AppData\Roaming\Python\Python310\site-packages\nornir_napalm\plugins\tasks\napalm_get.py", line 32, in napalm_get
    device = task.host.get_connection(CONNECTION_NAME, task.nornir.config)
  File "C:\Users\Admin\AppData\Roaming\Python\Python310\site-packages\nornir\core\inventory.py", line 494, in get_connection
    self.open_connection(
  File "C:\Users\Admin\AppData\Roaming\Python\Python310\site-packages\nornir\core\inventory.py", line 546, in open_connection
    conn_obj.open(
  File "C:\Users\Admin\AppData\Roaming\Python\Python310\site-packages\nornir_napalm\plugins\connections\__init__.py", line 55, in open
    network_driver = get_network_driver(platform)
  File "C:\Users\Admin\AppData\Roaming\Python\Python310\site-packages\napalm\base\__init__.py", line 68, in get_network_driver
    raise ModuleImportError("Please provide a valid driver name.")
napalm.base.exceptions.ModuleImportError: Please provide a valid driver name.

2022-02-17 13:07:56,562 - nornir.core.task -    ERROR -      start() - Host 'host1': task 'Backup Device configurations' failed with traceback:
Traceback (most recent call last):
  File "C:\Users\Admin\AppData\Roaming\Python\Python310\site-packages\nornir\core\task.py", line 99, in start
    r = self.task(self, **self.params)
  File "c:\Users\Admin\Documents\Code\Nornir\nornir\nornir_test.py", line 16, in backup_config
    device_config = task.run(task=napalm_get, getters=["get_config"])
  File "C:\Users\Admin\AppData\Roaming\Python\Python310\site-packages\nornir\core\task.py", line 174, in run
    raise NornirSubTaskError(task=run_task, result=r)
nornir.core.exceptions.NornirSubTaskError: Subtask: napalm_get (failed)


2022-02-17 13:12:02,624 -  nornir.core -     INFO -        run() - Running task 'Backup Device configurations' with args {'path': './data/configs'} on 1 hosts
2022-02-17 13:12:02,626 - nornir.core.task -    ERROR -      start() - Host 'host1': task 'napalm_get' failed with traceback:
Traceback (most recent call last):
  File "C:\Users\Admin\AppData\Roaming\Python\Python310\site-packages\nornir\core\task.py", line 99, in start
    r = self.task(self, **self.params)
  File "C:\Users\Admin\AppData\Roaming\Python\Python310\site-packages\nornir_napalm\plugins\tasks\napalm_get.py", line 32, in napalm_get
    device = task.host.get_connection(CONNECTION_NAME, task.nornir.config)
  File "C:\Users\Admin\AppData\Roaming\Python\Python310\site-packages\nornir\core\inventory.py", line 494, in get_connection
    self.open_connection(
  File "C:\Users\Admin\AppData\Roaming\Python\Python310\site-packages\nornir\core\inventory.py", line 546, in open_connection
    conn_obj.open(
  File "C:\Users\Admin\AppData\Roaming\Python\Python310\site-packages\nornir_napalm\plugins\connections\__init__.py", line 55, in open
    network_driver = get_network_driver(platform)
  File "C:\Users\Admin\AppData\Roaming\Python\Python310\site-packages\napalm\base\__init__.py", line 68, in get_network_driver
    raise ModuleImportError("Please provide a valid driver name.")
napalm.base.exceptions.ModuleImportError: Please provide a valid driver name.

2022-02-17 13:12:02,626 - nornir.core.task -    ERROR -      start() - Host 'host1': task 'Backup Device configurations' failed with traceback:
Traceback (most recent call last):
  File "C:\Users\Admin\AppData\Roaming\Python\Python310\site-packages\nornir\core\task.py", line 99, in start
    r = self.task(self, **self.params)
  File "c:\Users\Admin\Documents\Code\Nornir\nornir\nornir_test.py", line 16, in backup_config
    device_config = task.run(task=napalm_get, getters=["get_config"])
  File "C:\Users\Admin\AppData\Roaming\Python\Python310\site-packages\nornir\core\task.py", line 174, in run
    raise NornirSubTaskError(task=run_task, result=r)
nornir.core.exceptions.NornirSubTaskError: Subtask: napalm_get (failed)


2022-02-17 13:14:35,548 -  nornir.core -     INFO -        run() - Running task 'Backup Device configurations' with args {'path': './data/configs'} on 1 hosts
2022-02-17 13:14:37,604 - nornir.core.task -    ERROR -      start() - Host 'host1': task 'napalm_get' failed with traceback:
Traceback (most recent call last):
  File "C:\Users\Admin\AppData\Roaming\Python\Python310\site-packages\netmiko\base_connection.py", line 935, in establish_connection
    self.remote_conn_pre.connect(**ssh_connect_params)
  File "C:\Users\Admin\AppData\Roaming\Python\Python310\site-packages\paramiko\client.py", line 368, in connect
    raise NoValidConnectionsError(errors)
paramiko.ssh_exception.NoValidConnectionsError: [Errno None] Unable to connect to port 9000 on 127.0.0.1

During handling of the above exception, another exception occurred:

Traceback (most recent call last):
  File "C:\Users\Admin\AppData\Roaming\Python\Python310\site-packages\napalm\base\base.py", line 86, in _netmiko_open
    self._netmiko_device = ConnectHandler(
  File "C:\Users\Admin\AppData\Roaming\Python\Python310\site-packages\netmiko\ssh_dispatcher.py", line 326, in ConnectHandler
    return ConnectionClass(*args, **kwargs)
  File "C:\Users\Admin\AppData\Roaming\Python\Python310\site-packages\netmiko\cisco\cisco_ios.py", line 17, in __init__
    return super().__init__(*args, **kwargs)
  File "C:\Users\Admin\AppData\Roaming\Python\Python310\site-packages\netmiko\base_connection.py", line 350, in __init__
    self._open()
  File "C:\Users\Admin\AppData\Roaming\Python\Python310\site-packages\netmiko\base_connection.py", line 355, in _open
    self.establish_connection()
  File "C:\Users\Admin\AppData\Roaming\Python\Python310\site-packages\netmiko\base_connection.py", line 957, in establish_connection
    raise NetmikoTimeoutException(msg)
netmiko.ssh_exception.NetmikoTimeoutException: TCP connection to device failed.

Common causes of this problem are:
1. Incorrect hostname or IP address.
2. Wrong TCP port.
3. Intermediate firewall blocking access.

Device settings: cisco_ios 127.0.0.1:9000



During handling of the above exception, another exception occurred:

Traceback (most recent call last):
  File "C:\Users\Admin\AppData\Roaming\Python\Python310\site-packages\nornir\core\task.py", line 99, in start
    r = self.task(self, **self.params)
  File "C:\Users\Admin\AppData\Roaming\Python\Python310\site-packages\nornir_napalm\plugins\tasks\napalm_get.py", line 32, in napalm_get
    device = task.host.get_connection(CONNECTION_NAME, task.nornir.config)
  File "C:\Users\Admin\AppData\Roaming\Python\Python310\site-packages\nornir\core\inventory.py", line 494, in get_connection
    self.open_connection(
  File "C:\Users\Admin\AppData\Roaming\Python\Python310\site-packages\nornir\core\inventory.py", line 546, in open_connection
    conn_obj.open(
  File "C:\Users\Admin\AppData\Roaming\Python\Python310\site-packages\nornir_napalm\plugins\connections\__init__.py", line 57, in open
    connection.open()
  File "C:\Users\Admin\AppData\Roaming\Python\Python310\site-packages\napalm\ios\ios.py", line 169, in open
    self.device = self._netmiko_open(
  File "C:\Users\Admin\AppData\Roaming\Python\Python310\site-packages\napalm\base\base.py", line 95, in _netmiko_open
    raise ConnectionException("Cannot connect to {}".format(self.hostname))
napalm.base.exceptions.ConnectionException: Cannot connect to 127.0.0.1

2022-02-17 13:14:37,605 - nornir.core.task -    ERROR -      start() - Host 'host1': task 'Backup Device configurations' failed with traceback:
Traceback (most recent call last):
  File "C:\Users\Admin\AppData\Roaming\Python\Python310\site-packages\nornir\core\task.py", line 99, in start
    r = self.task(self, **self.params)
  File "c:\Users\Admin\Documents\Code\Nornir\nornir\nornir_test.py", line 16, in backup_config
    device_config = task.run(task=napalm_get, getters=["get_config"])
  File "C:\Users\Admin\AppData\Roaming\Python\Python310\site-packages\nornir\core\task.py", line 174, in run
    raise NornirSubTaskError(task=run_task, result=r)
nornir.core.exceptions.NornirSubTaskError: Subtask: napalm_get (failed)


2022-02-17 13:15:39,951 -  nornir.core -     INFO -        run() - Running task 'Backup Device configurations' with args {'path': './data/configs'} on 1 hosts
2022-02-17 13:15:42,002 - nornir.core.task -    ERROR -      start() - Host 'host1': task 'napalm_get' failed with traceback:
Traceback (most recent call last):
  File "C:\Users\Admin\AppData\Roaming\Python\Python310\site-packages\netmiko\base_connection.py", line 935, in establish_connection
    self.remote_conn_pre.connect(**ssh_connect_params)
  File "C:\Users\Admin\AppData\Roaming\Python\Python310\site-packages\paramiko\client.py", line 368, in connect
    raise NoValidConnectionsError(errors)
paramiko.ssh_exception.NoValidConnectionsError: [Errno None] Unable to connect to port 9000 on 127.0.0.1

During handling of the above exception, another exception occurred:

Traceback (most recent call last):
  File "C:\Users\Admin\AppData\Roaming\Python\Python310\site-packages\napalm\base\base.py", line 86, in _netmiko_open
    self._netmiko_device = ConnectHandler(
  File "C:\Users\Admin\AppData\Roaming\Python\Python310\site-packages\netmiko\ssh_dispatcher.py", line 326, in ConnectHandler
    return ConnectionClass(*args, **kwargs)
  File "C:\Users\Admin\AppData\Roaming\Python\Python310\site-packages\netmiko\cisco\cisco_ios.py", line 17, in __init__
    return super().__init__(*args, **kwargs)
  File "C:\Users\Admin\AppData\Roaming\Python\Python310\site-packages\netmiko\base_connection.py", line 350, in __init__
    self._open()
  File "C:\Users\Admin\AppData\Roaming\Python\Python310\site-packages\netmiko\base_connection.py", line 355, in _open
    self.establish_connection()
  File "C:\Users\Admin\AppData\Roaming\Python\Python310\site-packages\netmiko\base_connection.py", line 957, in establish_connection
    raise NetmikoTimeoutException(msg)
netmiko.ssh_exception.NetmikoTimeoutException: TCP connection to device failed.

Common causes of this problem are:
1. Incorrect hostname or IP address.
2. Wrong TCP port.
3. Intermediate firewall blocking access.

Device settings: cisco_ios 127.0.0.1:9000



During handling of the above exception, another exception occurred:

Traceback (most recent call last):
  File "C:\Users\Admin\AppData\Roaming\Python\Python310\site-packages\nornir\core\task.py", line 99, in start
    r = self.task(self, **self.params)
  File "C:\Users\Admin\AppData\Roaming\Python\Python310\site-packages\nornir_napalm\plugins\tasks\napalm_get.py", line 32, in napalm_get
    device = task.host.get_connection(CONNECTION_NAME, task.nornir.config)
  File "C:\Users\Admin\AppData\Roaming\Python\Python310\site-packages\nornir\core\inventory.py", line 494, in get_connection
    self.open_connection(
  File "C:\Users\Admin\AppData\Roaming\Python\Python310\site-packages\nornir\core\inventory.py", line 546, in open_connection
    conn_obj.open(
  File "C:\Users\Admin\AppData\Roaming\Python\Python310\site-packages\nornir_napalm\plugins\connections\__init__.py", line 57, in open
    connection.open()
  File "C:\Users\Admin\AppData\Roaming\Python\Python310\site-packages\napalm\ios\ios.py", line 169, in open
    self.device = self._netmiko_open(
  File "C:\Users\Admin\AppData\Roaming\Python\Python310\site-packages\napalm\base\base.py", line 95, in _netmiko_open
    raise ConnectionException("Cannot connect to {}".format(self.hostname))
napalm.base.exceptions.ConnectionException: Cannot connect to 127.0.0.1

2022-02-17 13:15:42,002 - nornir.core.task -    ERROR -      start() - Host 'host1': task 'Backup Device configurations' failed with traceback:
Traceback (most recent call last):
  File "C:\Users\Admin\AppData\Roaming\Python\Python310\site-packages\nornir\core\task.py", line 99, in start
    r = self.task(self, **self.params)
  File "c:\Users\Admin\Documents\Code\Nornir\nornir\nornir_test.py", line 16, in backup_config
    device_config = task.run(task=napalm_get, getters=["get_config"])
  File "C:\Users\Admin\AppData\Roaming\Python\Python310\site-packages\nornir\core\task.py", line 174, in run
    raise NornirSubTaskError(task=run_task, result=r)
nornir.core.exceptions.NornirSubTaskError: Subtask: napalm_get (failed)


2022-02-17 13:16:41,519 -  nornir.core -     INFO -        run() - Running task 'Backup Device configurations' with args {'path': './data/configs'} on 1 hosts
2022-02-17 13:16:43,576 - nornir.core.task -    ERROR -      start() - Host 'host1': task 'napalm_get' failed with traceback:
Traceback (most recent call last):
  File "C:\Users\Admin\AppData\Roaming\Python\Python310\site-packages\netmiko\base_connection.py", line 935, in establish_connection
    self.remote_conn_pre.connect(**ssh_connect_params)
  File "C:\Users\Admin\AppData\Roaming\Python\Python310\site-packages\paramiko\client.py", line 368, in connect
    raise NoValidConnectionsError(errors)
paramiko.ssh_exception.NoValidConnectionsError: [Errno None] Unable to connect to port 9000 on 127.0.0.1

During handling of the above exception, another exception occurred:

Traceback (most recent call last):
  File "C:\Users\Admin\AppData\Roaming\Python\Python310\site-packages\napalm\base\base.py", line 86, in _netmiko_open
    self._netmiko_device = ConnectHandler(
  File "C:\Users\Admin\AppData\Roaming\Python\Python310\site-packages\netmiko\ssh_dispatcher.py", line 326, in ConnectHandler
    return ConnectionClass(*args, **kwargs)
  File "C:\Users\Admin\AppData\Roaming\Python\Python310\site-packages\netmiko\cisco\cisco_ios.py", line 17, in __init__
    return super().__init__(*args, **kwargs)
  File "C:\Users\Admin\AppData\Roaming\Python\Python310\site-packages\netmiko\base_connection.py", line 350, in __init__
    self._open()
  File "C:\Users\Admin\AppData\Roaming\Python\Python310\site-packages\netmiko\base_connection.py", line 355, in _open
    self.establish_connection()
  File "C:\Users\Admin\AppData\Roaming\Python\Python310\site-packages\netmiko\base_connection.py", line 957, in establish_connection
    raise NetmikoTimeoutException(msg)
netmiko.ssh_exception.NetmikoTimeoutException: TCP connection to device failed.

Common causes of this problem are:
1. Incorrect hostname or IP address.
2. Wrong TCP port.
3. Intermediate firewall blocking access.

Device settings: cisco_ios 127.0.0.1:9000



During handling of the above exception, another exception occurred:

Traceback (most recent call last):
  File "C:\Users\Admin\AppData\Roaming\Python\Python310\site-packages\nornir\core\task.py", line 99, in start
    r = self.task(self, **self.params)
  File "C:\Users\Admin\AppData\Roaming\Python\Python310\site-packages\nornir_napalm\plugins\tasks\napalm_get.py", line 32, in napalm_get
    device = task.host.get_connection(CONNECTION_NAME, task.nornir.config)
  File "C:\Users\Admin\AppData\Roaming\Python\Python310\site-packages\nornir\core\inventory.py", line 494, in get_connection
    self.open_connection(
  File "C:\Users\Admin\AppData\Roaming\Python\Python310\site-packages\nornir\core\inventory.py", line 546, in open_connection
    conn_obj.open(
  File "C:\Users\Admin\AppData\Roaming\Python\Python310\site-packages\nornir_napalm\plugins\connections\__init__.py", line 57, in open
    connection.open()
  File "C:\Users\Admin\AppData\Roaming\Python\Python310\site-packages\napalm\ios\ios.py", line 169, in open
    self.device = self._netmiko_open(
  File "C:\Users\Admin\AppData\Roaming\Python\Python310\site-packages\napalm\base\base.py", line 95, in _netmiko_open
    raise ConnectionException("Cannot connect to {}".format(self.hostname))
napalm.base.exceptions.ConnectionException: Cannot connect to 127.0.0.1

2022-02-17 13:16:43,576 - nornir.core.task -    ERROR -      start() - Host 'host1': task 'Backup Device configurations' failed with traceback:
Traceback (most recent call last):
  File "C:\Users\Admin\AppData\Roaming\Python\Python310\site-packages\nornir\core\task.py", line 99, in start
    r = self.task(self, **self.params)
  File "c:\Users\Admin\Documents\Code\Nornir\nornir\nornir_test.py", line 16, in backup_config
    device_config = task.run(task=napalm_get, getters=["get_config"])
  File "C:\Users\Admin\AppData\Roaming\Python\Python310\site-packages\nornir\core\task.py", line 174, in run
    raise NornirSubTaskError(task=run_task, result=r)
nornir.core.exceptions.NornirSubTaskError: Subtask: napalm_get (failed)


2022-02-17 13:17:45,328 -  nornir.core -     INFO -        run() - Running task 'Backup Device configurations' with args {'path': './data/configs'} on 1 hosts
2022-02-17 13:17:47,402 - nornir.core.task -    ERROR -      start() - Host 'host1': task 'napalm_get' failed with traceback:
Traceback (most recent call last):
  File "C:\Users\Admin\AppData\Roaming\Python\Python310\site-packages\netmiko\base_connection.py", line 935, in establish_connection
    self.remote_conn_pre.connect(**ssh_connect_params)
  File "C:\Users\Admin\AppData\Roaming\Python\Python310\site-packages\paramiko\client.py", line 368, in connect
    raise NoValidConnectionsError(errors)
paramiko.ssh_exception.NoValidConnectionsError: [Errno None] Unable to connect to port 9000 on 127.0.0.1

During handling of the above exception, another exception occurred:

Traceback (most recent call last):
  File "C:\Users\Admin\AppData\Roaming\Python\Python310\site-packages\napalm\base\base.py", line 86, in _netmiko_open
    self._netmiko_device = ConnectHandler(
  File "C:\Users\Admin\AppData\Roaming\Python\Python310\site-packages\netmiko\ssh_dispatcher.py", line 326, in ConnectHandler
    return ConnectionClass(*args, **kwargs)
  File "C:\Users\Admin\AppData\Roaming\Python\Python310\site-packages\netmiko\cisco\cisco_ios.py", line 17, in __init__
    return super().__init__(*args, **kwargs)
  File "C:\Users\Admin\AppData\Roaming\Python\Python310\site-packages\netmiko\base_connection.py", line 350, in __init__
    self._open()
  File "C:\Users\Admin\AppData\Roaming\Python\Python310\site-packages\netmiko\base_connection.py", line 355, in _open
    self.establish_connection()
  File "C:\Users\Admin\AppData\Roaming\Python\Python310\site-packages\netmiko\base_connection.py", line 957, in establish_connection
    raise NetmikoTimeoutException(msg)
netmiko.ssh_exception.NetmikoTimeoutException: TCP connection to device failed.

Common causes of this problem are:
1. Incorrect hostname or IP address.
2. Wrong TCP port.
3. Intermediate firewall blocking access.

Device settings: cisco_ios 127.0.0.1:9000



During handling of the above exception, another exception occurred:

Traceback (most recent call last):
  File "C:\Users\Admin\AppData\Roaming\Python\Python310\site-packages\nornir\core\task.py", line 99, in start
    r = self.task(self, **self.params)
  File "C:\Users\Admin\AppData\Roaming\Python\Python310\site-packages\nornir_napalm\plugins\tasks\napalm_get.py", line 32, in napalm_get
    device = task.host.get_connection(CONNECTION_NAME, task.nornir.config)
  File "C:\Users\Admin\AppData\Roaming\Python\Python310\site-packages\nornir\core\inventory.py", line 494, in get_connection
    self.open_connection(
  File "C:\Users\Admin\AppData\Roaming\Python\Python310\site-packages\nornir\core\inventory.py", line 546, in open_connection
    conn_obj.open(
  File "C:\Users\Admin\AppData\Roaming\Python\Python310\site-packages\nornir_napalm\plugins\connections\__init__.py", line 57, in open
    connection.open()
  File "C:\Users\Admin\AppData\Roaming\Python\Python310\site-packages\napalm\ios\ios.py", line 169, in open
    self.device = self._netmiko_open(
  File "C:\Users\Admin\AppData\Roaming\Python\Python310\site-packages\napalm\base\base.py", line 95, in _netmiko_open
    raise ConnectionException("Cannot connect to {}".format(self.hostname))
napalm.base.exceptions.ConnectionException: Cannot connect to 127.0.0.1

2022-02-17 13:17:47,402 - nornir.core.task -    ERROR -      start() - Host 'host1': task 'Backup Device configurations' failed with traceback:
Traceback (most recent call last):
  File "C:\Users\Admin\AppData\Roaming\Python\Python310\site-packages\nornir\core\task.py", line 99, in start
    r = self.task(self, **self.params)
  File "c:\Users\Admin\Documents\Code\Nornir\nornir\nornir_test.py", line 16, in backup_config
    device_config = task.run(task=napalm_get, getters=["get_config"])
  File "C:\Users\Admin\AppData\Roaming\Python\Python310\site-packages\nornir\core\task.py", line 174, in run
    raise NornirSubTaskError(task=run_task, result=r)
nornir.core.exceptions.NornirSubTaskError: Subtask: napalm_get (failed)


2022-02-17 13:19:09,092 -  nornir.core -     INFO -        run() - Running task 'Backup Device configurations' with args {'path': './data/configs'} on 1 hosts
2022-02-17 13:19:11,132 - nornir.core.task -    ERROR -      start() - Host 'host1': task 'napalm_get' failed with traceback:
Traceback (most recent call last):
  File "C:\Users\Admin\AppData\Roaming\Python\Python310\site-packages\netmiko\base_connection.py", line 935, in establish_connection
    self.remote_conn_pre.connect(**ssh_connect_params)
  File "C:\Users\Admin\AppData\Roaming\Python\Python310\site-packages\paramiko\client.py", line 368, in connect
    raise NoValidConnectionsError(errors)
paramiko.ssh_exception.NoValidConnectionsError: [Errno None] Unable to connect to port 9000 on 127.0.0.1

During handling of the above exception, another exception occurred:

Traceback (most recent call last):
  File "C:\Users\Admin\AppData\Roaming\Python\Python310\site-packages\napalm\base\base.py", line 86, in _netmiko_open
    self._netmiko_device = ConnectHandler(
  File "C:\Users\Admin\AppData\Roaming\Python\Python310\site-packages\netmiko\ssh_dispatcher.py", line 326, in ConnectHandler
    return ConnectionClass(*args, **kwargs)
  File "C:\Users\Admin\AppData\Roaming\Python\Python310\site-packages\netmiko\cisco\cisco_ios.py", line 17, in __init__
    return super().__init__(*args, **kwargs)
  File "C:\Users\Admin\AppData\Roaming\Python\Python310\site-packages\netmiko\base_connection.py", line 350, in __init__
    self._open()
  File "C:\Users\Admin\AppData\Roaming\Python\Python310\site-packages\netmiko\base_connection.py", line 355, in _open
    self.establish_connection()
  File "C:\Users\Admin\AppData\Roaming\Python\Python310\site-packages\netmiko\base_connection.py", line 957, in establish_connection
    raise NetmikoTimeoutException(msg)
netmiko.ssh_exception.NetmikoTimeoutException: TCP connection to device failed.

Common causes of this problem are:
1. Incorrect hostname or IP address.
2. Wrong TCP port.
3. Intermediate firewall blocking access.

Device settings: cisco_ios 127.0.0.1:9000



During handling of the above exception, another exception occurred:

Traceback (most recent call last):
  File "C:\Users\Admin\AppData\Roaming\Python\Python310\site-packages\nornir\core\task.py", line 99, in start
    r = self.task(self, **self.params)
  File "C:\Users\Admin\AppData\Roaming\Python\Python310\site-packages\nornir_napalm\plugins\tasks\napalm_get.py", line 32, in napalm_get
    device = task.host.get_connection(CONNECTION_NAME, task.nornir.config)
  File "C:\Users\Admin\AppData\Roaming\Python\Python310\site-packages\nornir\core\inventory.py", line 494, in get_connection
    self.open_connection(
  File "C:\Users\Admin\AppData\Roaming\Python\Python310\site-packages\nornir\core\inventory.py", line 546, in open_connection
    conn_obj.open(
  File "C:\Users\Admin\AppData\Roaming\Python\Python310\site-packages\nornir_napalm\plugins\connections\__init__.py", line 57, in open
    connection.open()
  File "C:\Users\Admin\AppData\Roaming\Python\Python310\site-packages\napalm\ios\ios.py", line 169, in open
    self.device = self._netmiko_open(
  File "C:\Users\Admin\AppData\Roaming\Python\Python310\site-packages\napalm\base\base.py", line 95, in _netmiko_open
    raise ConnectionException("Cannot connect to {}".format(self.hostname))
napalm.base.exceptions.ConnectionException: Cannot connect to 127.0.0.1

2022-02-17 13:19:11,132 - nornir.core.task -    ERROR -      start() - Host 'host1': task 'Backup Device configurations' failed with traceback:
Traceback (most recent call last):
  File "C:\Users\Admin\AppData\Roaming\Python\Python310\site-packages\nornir\core\task.py", line 99, in start
    r = self.task(self, **self.params)
  File "c:\Users\Admin\Documents\Code\Nornir\nornir\nornir_test.py", line 16, in backup_config
    device_config = task.run(task=napalm_get, getters=["get_config"])
  File "C:\Users\Admin\AppData\Roaming\Python\Python310\site-packages\nornir\core\task.py", line 174, in run
    raise NornirSubTaskError(task=run_task, result=r)
nornir.core.exceptions.NornirSubTaskError: Subtask: napalm_get (failed)


2022-02-17 13:20:02,506 -  nornir.core -     INFO -        run() - Running task 'Backup Device configurations' with args {'path': './data/configs'} on 1 hosts
2022-02-17 13:20:04,567 - nornir.core.task -    ERROR -      start() - Host 'host1': task 'napalm_get' failed with traceback:
Traceback (most recent call last):
  File "C:\Users\Admin\AppData\Roaming\Python\Python310\site-packages\netmiko\base_connection.py", line 935, in establish_connection
    self.remote_conn_pre.connect(**ssh_connect_params)
  File "C:\Users\Admin\AppData\Roaming\Python\Python310\site-packages\paramiko\client.py", line 368, in connect
    raise NoValidConnectionsError(errors)
paramiko.ssh_exception.NoValidConnectionsError: [Errno None] Unable to connect to port 9000 on 127.0.0.1

During handling of the above exception, another exception occurred:

Traceback (most recent call last):
  File "C:\Users\Admin\AppData\Roaming\Python\Python310\site-packages\napalm\base\base.py", line 86, in _netmiko_open
    self._netmiko_device = ConnectHandler(
  File "C:\Users\Admin\AppData\Roaming\Python\Python310\site-packages\netmiko\ssh_dispatcher.py", line 326, in ConnectHandler
    return ConnectionClass(*args, **kwargs)
  File "C:\Users\Admin\AppData\Roaming\Python\Python310\site-packages\netmiko\cisco\cisco_ios.py", line 17, in __init__
    return super().__init__(*args, **kwargs)
  File "C:\Users\Admin\AppData\Roaming\Python\Python310\site-packages\netmiko\base_connection.py", line 350, in __init__
    self._open()
  File "C:\Users\Admin\AppData\Roaming\Python\Python310\site-packages\netmiko\base_connection.py", line 355, in _open
    self.establish_connection()
  File "C:\Users\Admin\AppData\Roaming\Python\Python310\site-packages\netmiko\base_connection.py", line 957, in establish_connection
    raise NetmikoTimeoutException(msg)
netmiko.ssh_exception.NetmikoTimeoutException: TCP connection to device failed.

Common causes of this problem are:
1. Incorrect hostname or IP address.
2. Wrong TCP port.
3. Intermediate firewall blocking access.

Device settings: cisco_ios 127.0.0.1:9000



During handling of the above exception, another exception occurred:

Traceback (most recent call last):
  File "C:\Users\Admin\AppData\Roaming\Python\Python310\site-packages\nornir\core\task.py", line 99, in start
    r = self.task(self, **self.params)
  File "C:\Users\Admin\AppData\Roaming\Python\Python310\site-packages\nornir_napalm\plugins\tasks\napalm_get.py", line 32, in napalm_get
    device = task.host.get_connection(CONNECTION_NAME, task.nornir.config)
  File "C:\Users\Admin\AppData\Roaming\Python\Python310\site-packages\nornir\core\inventory.py", line 494, in get_connection
    self.open_connection(
  File "C:\Users\Admin\AppData\Roaming\Python\Python310\site-packages\nornir\core\inventory.py", line 546, in open_connection
    conn_obj.open(
  File "C:\Users\Admin\AppData\Roaming\Python\Python310\site-packages\nornir_napalm\plugins\connections\__init__.py", line 57, in open
    connection.open()
  File "C:\Users\Admin\AppData\Roaming\Python\Python310\site-packages\napalm\ios\ios.py", line 169, in open
    self.device = self._netmiko_open(
  File "C:\Users\Admin\AppData\Roaming\Python\Python310\site-packages\napalm\base\base.py", line 95, in _netmiko_open
    raise ConnectionException("Cannot connect to {}".format(self.hostname))
napalm.base.exceptions.ConnectionException: Cannot connect to 127.0.0.1

2022-02-17 13:20:04,567 - nornir.core.task -    ERROR -      start() - Host 'host1': task 'Backup Device configurations' failed with traceback:
Traceback (most recent call last):
  File "C:\Users\Admin\AppData\Roaming\Python\Python310\site-packages\nornir\core\task.py", line 99, in start
    r = self.task(self, **self.params)
  File "c:\Users\Admin\Documents\Code\Nornir\nornir\nornir_test.py", line 16, in backup_config
    device_config = task.run(task=napalm_get, getters=["get_config"])
  File "C:\Users\Admin\AppData\Roaming\Python\Python310\site-packages\nornir\core\task.py", line 174, in run
    raise NornirSubTaskError(task=run_task, result=r)
nornir.core.exceptions.NornirSubTaskError: Subtask: napalm_get (failed)


2022-02-17 13:21:51,547 -  nornir.core -     INFO -        run() - Running task 'Backup Device configurations' with args {'path': './data/configs'} on 1 hosts
2022-02-17 13:21:51,550 - nornir.core.task -    ERROR -      start() - Host 'host1': task 'napalm_get' failed with traceback:
Traceback (most recent call last):
  File "C:\Users\Admin\AppData\Roaming\Python\Python310\site-packages\nornir\core\task.py", line 99, in start
    r = self.task(self, **self.params)
  File "C:\Users\Admin\AppData\Roaming\Python\Python310\site-packages\nornir_napalm\plugins\tasks\napalm_get.py", line 32, in napalm_get
    device = task.host.get_connection(CONNECTION_NAME, task.nornir.config)
  File "C:\Users\Admin\AppData\Roaming\Python\Python310\site-packages\nornir\core\inventory.py", line 494, in get_connection
    self.open_connection(
  File "C:\Users\Admin\AppData\Roaming\Python\Python310\site-packages\nornir\core\inventory.py", line 546, in open_connection
    conn_obj.open(
  File "C:\Users\Admin\AppData\Roaming\Python\Python310\site-packages\nornir_napalm\plugins\connections\__init__.py", line 55, in open
    network_driver = get_network_driver(platform)
  File "C:\Users\Admin\AppData\Roaming\Python\Python310\site-packages\napalm\base\__init__.py", line 97, in get_network_driver
    raise ModuleImportError(
napalm.base.exceptions.ModuleImportError: Cannot import "cisco_ios_telnet". Is the library installed?

2022-02-17 13:21:51,550 - nornir.core.task -    ERROR -      start() - Host 'host1': task 'Backup Device configurations' failed with traceback:
Traceback (most recent call last):
  File "C:\Users\Admin\AppData\Roaming\Python\Python310\site-packages\nornir\core\task.py", line 99, in start
    r = self.task(self, **self.params)
  File "c:\Users\Admin\Documents\Code\Nornir\nornir\nornir_test.py", line 16, in backup_config
    device_config = task.run(task=napalm_get, getters=["get_config"])
  File "C:\Users\Admin\AppData\Roaming\Python\Python310\site-packages\nornir\core\task.py", line 174, in run
    raise NornirSubTaskError(task=run_task, result=r)
nornir.core.exceptions.NornirSubTaskError: Subtask: napalm_get (failed)


2022-02-17 13:24:01,826 -  nornir.core -     INFO -        run() - Running task 'Backup Device configurations' with args {'path': './data/configs'} on 1 hosts
2022-02-17 13:24:03,873 - nornir.core.task -    ERROR -      start() - Host 'host1': task 'napalm_get' failed with traceback:
Traceback (most recent call last):
  File "C:\Users\Admin\AppData\Roaming\Python\Python310\site-packages\netmiko\base_connection.py", line 935, in establish_connection
    self.remote_conn_pre.connect(**ssh_connect_params)
  File "C:\Users\Admin\AppData\Roaming\Python\Python310\site-packages\paramiko\client.py", line 368, in connect
    raise NoValidConnectionsError(errors)
paramiko.ssh_exception.NoValidConnectionsError: [Errno None] Unable to connect to port 9000 on 127.0.0.1

During handling of the above exception, another exception occurred:

Traceback (most recent call last):
  File "C:\Users\Admin\AppData\Roaming\Python\Python310\site-packages\napalm\base\base.py", line 86, in _netmiko_open
    self._netmiko_device = ConnectHandler(
  File "C:\Users\Admin\AppData\Roaming\Python\Python310\site-packages\netmiko\ssh_dispatcher.py", line 326, in ConnectHandler
    return ConnectionClass(*args, **kwargs)
  File "C:\Users\Admin\AppData\Roaming\Python\Python310\site-packages\netmiko\cisco\cisco_ios.py", line 17, in __init__
    return super().__init__(*args, **kwargs)
  File "C:\Users\Admin\AppData\Roaming\Python\Python310\site-packages\netmiko\base_connection.py", line 350, in __init__
    self._open()
  File "C:\Users\Admin\AppData\Roaming\Python\Python310\site-packages\netmiko\base_connection.py", line 355, in _open
    self.establish_connection()
  File "C:\Users\Admin\AppData\Roaming\Python\Python310\site-packages\netmiko\base_connection.py", line 957, in establish_connection
    raise NetmikoTimeoutException(msg)
netmiko.ssh_exception.NetmikoTimeoutException: TCP connection to device failed.

Common causes of this problem are:
1. Incorrect hostname or IP address.
2. Wrong TCP port.
3. Intermediate firewall blocking access.

Device settings: cisco_ios 127.0.0.1:9000



During handling of the above exception, another exception occurred:

Traceback (most recent call last):
  File "C:\Users\Admin\AppData\Roaming\Python\Python310\site-packages\nornir\core\task.py", line 99, in start
    r = self.task(self, **self.params)
  File "C:\Users\Admin\AppData\Roaming\Python\Python310\site-packages\nornir_napalm\plugins\tasks\napalm_get.py", line 32, in napalm_get
    device = task.host.get_connection(CONNECTION_NAME, task.nornir.config)
  File "C:\Users\Admin\AppData\Roaming\Python\Python310\site-packages\nornir\core\inventory.py", line 494, in get_connection
    self.open_connection(
  File "C:\Users\Admin\AppData\Roaming\Python\Python310\site-packages\nornir\core\inventory.py", line 546, in open_connection
    conn_obj.open(
  File "C:\Users\Admin\AppData\Roaming\Python\Python310\site-packages\nornir_napalm\plugins\connections\__init__.py", line 57, in open
    connection.open()
  File "C:\Users\Admin\AppData\Roaming\Python\Python310\site-packages\napalm\ios\ios.py", line 169, in open
    self.device = self._netmiko_open(
  File "C:\Users\Admin\AppData\Roaming\Python\Python310\site-packages\napalm\base\base.py", line 95, in _netmiko_open
    raise ConnectionException("Cannot connect to {}".format(self.hostname))
napalm.base.exceptions.ConnectionException: Cannot connect to 127.0.0.1

2022-02-17 13:24:03,875 - nornir.core.task -    ERROR -      start() - Host 'host1': task 'Backup Device configurations' failed with traceback:
Traceback (most recent call last):
  File "C:\Users\Admin\AppData\Roaming\Python\Python310\site-packages\nornir\core\task.py", line 99, in start
    r = self.task(self, **self.params)
  File "c:\Users\Admin\Documents\Code\Nornir\nornir\nornir_test.py", line 16, in backup_config
    device_config = task.run(task=napalm_get, getters=["get_config"])
  File "C:\Users\Admin\AppData\Roaming\Python\Python310\site-packages\nornir\core\task.py", line 174, in run
    raise NornirSubTaskError(task=run_task, result=r)
nornir.core.exceptions.NornirSubTaskError: Subtask: napalm_get (failed)


2022-02-17 13:38:58,391 -  nornir.core -     INFO -        run() - Running task 'Backup Device configurations' with args {'path': './data/configs'} on 1 hosts
2022-02-17 13:38:58,803 - nornir.core.task -    ERROR -      start() - Host 'host1': task 'napalm_get' failed with traceback:
Traceback (most recent call last):
  File "C:\Users\Admin\AppData\Roaming\Python\Python310\site-packages\paramiko\transport.py", line 2211, in _check_banner
    buf = self.packetizer.readline(timeout)
  File "C:\Users\Admin\AppData\Roaming\Python\Python310\site-packages\paramiko\packet.py", line 386, in readline
    return u(buf)
  File "C:\Users\Admin\AppData\Roaming\Python\Python310\site-packages\paramiko\py3compat.py", line 147, in u
    return s.decode(encoding)
UnicodeDecodeError: 'utf-8' codec can't decode byte 0xff in position 0: invalid start byte

During handling of the above exception, another exception occurred:

Traceback (most recent call last):
  File "C:\Users\Admin\AppData\Roaming\Python\Python310\site-packages\nornir\core\task.py", line 99, in start
    r = self.task(self, **self.params)
  File "C:\Users\Admin\AppData\Roaming\Python\Python310\site-packages\nornir_napalm\plugins\tasks\napalm_get.py", line 32, in napalm_get
    device = task.host.get_connection(CONNECTION_NAME, task.nornir.config)
  File "C:\Users\Admin\AppData\Roaming\Python\Python310\site-packages\nornir\core\inventory.py", line 494, in get_connection
    self.open_connection(
  File "C:\Users\Admin\AppData\Roaming\Python\Python310\site-packages\nornir\core\inventory.py", line 546, in open_connection
    conn_obj.open(
  File "C:\Users\Admin\AppData\Roaming\Python\Python310\site-packages\nornir_napalm\plugins\connections\__init__.py", line 57, in open
    connection.open()
  File "C:\Users\Admin\AppData\Roaming\Python\Python310\site-packages\napalm\ios\ios.py", line 169, in open
    self.device = self._netmiko_open(
  File "C:\Users\Admin\AppData\Roaming\Python\Python310\site-packages\napalm\base\base.py", line 86, in _netmiko_open
    self._netmiko_device = ConnectHandler(
  File "C:\Users\Admin\AppData\Roaming\Python\Python310\site-packages\netmiko\ssh_dispatcher.py", line 326, in ConnectHandler
    return ConnectionClass(*args, **kwargs)
  File "C:\Users\Admin\AppData\Roaming\Python\Python310\site-packages\netmiko\cisco\cisco_ios.py", line 17, in __init__
    return super().__init__(*args, **kwargs)
  File "C:\Users\Admin\AppData\Roaming\Python\Python310\site-packages\netmiko\base_connection.py", line 350, in __init__
    self._open()
  File "C:\Users\Admin\AppData\Roaming\Python\Python310\site-packages\netmiko\base_connection.py", line 355, in _open
    self.establish_connection()
  File "C:\Users\Admin\AppData\Roaming\Python\Python310\site-packages\netmiko\base_connection.py", line 935, in establish_connection
    self.remote_conn_pre.connect(**ssh_connect_params)
  File "C:\Users\Admin\AppData\Roaming\Python\Python310\site-packages\paramiko\client.py", line 406, in connect
    t.start_client(timeout=timeout)
  File "C:\Users\Admin\AppData\Roaming\Python\Python310\site-packages\paramiko\transport.py", line 660, in start_client
    raise e
  File "C:\Users\Admin\AppData\Roaming\Python\Python310\site-packages\paramiko\transport.py", line 2039, in run
    self._check_banner()
  File "C:\Users\Admin\AppData\Roaming\Python\Python310\site-packages\paramiko\transport.py", line 2215, in _check_banner
    raise SSHException(
paramiko.ssh_exception.SSHException: Error reading SSH protocol banner'utf-8' codec can't decode byte 0xff in position 0: invalid start byte

2022-02-17 13:38:58,804 - nornir.core.task -    ERROR -      start() - Host 'host1': task 'Backup Device configurations' failed with traceback:
Traceback (most recent call last):
  File "C:\Users\Admin\AppData\Roaming\Python\Python310\site-packages\nornir\core\task.py", line 99, in start
    r = self.task(self, **self.params)
  File "c:\Users\Admin\Documents\Code\Nornir\nornir\nornir_test.py", line 16, in backup_config
    device_config = task.run(task=napalm_get, getters=["get_config"])
  File "C:\Users\Admin\AppData\Roaming\Python\Python310\site-packages\nornir\core\task.py", line 174, in run
    raise NornirSubTaskError(task=run_task, result=r)
nornir.core.exceptions.NornirSubTaskError: Subtask: napalm_get (failed)


2022-02-17 13:40:05,102 -  nornir.core -     INFO -        run() - Running task 'Backup Device configurations' with args {'path': './data/configs'} on 1 hosts
2022-02-17 13:40:05,102 - nornir.core.task -    ERROR -      start() - Host 'host1': task 'napalm_get' failed with traceback:
Traceback (most recent call last):
  File "C:\Users\Admin\AppData\Roaming\Python\Python310\site-packages\nornir\core\task.py", line 99, in start
    r = self.task(self, **self.params)
  File "C:\Users\Admin\AppData\Roaming\Python\Python310\site-packages\nornir_napalm\plugins\tasks\napalm_get.py", line 32, in napalm_get
    device = task.host.get_connection(CONNECTION_NAME, task.nornir.config)
  File "C:\Users\Admin\AppData\Roaming\Python\Python310\site-packages\nornir\core\inventory.py", line 494, in get_connection
    self.open_connection(
  File "C:\Users\Admin\AppData\Roaming\Python\Python310\site-packages\nornir\core\inventory.py", line 546, in open_connection
    conn_obj.open(
  File "C:\Users\Admin\AppData\Roaming\Python\Python310\site-packages\nornir_napalm\plugins\connections\__init__.py", line 55, in open
    network_driver = get_network_driver(platform)
  File "C:\Users\Admin\AppData\Roaming\Python\Python310\site-packages\napalm\base\__init__.py", line 68, in get_network_driver
    raise ModuleImportError("Please provide a valid driver name.")
napalm.base.exceptions.ModuleImportError: Please provide a valid driver name.

2022-02-17 13:40:05,102 - nornir.core.task -    ERROR -      start() - Host 'host1': task 'Backup Device configurations' failed with traceback:
Traceback (most recent call last):
  File "C:\Users\Admin\AppData\Roaming\Python\Python310\site-packages\nornir\core\task.py", line 99, in start
    r = self.task(self, **self.params)
  File "c:\Users\Admin\Documents\Code\Nornir\nornir\nornir_test.py", line 16, in backup_config
    device_config = task.run(task=napalm_get, getters=["get_config"])
  File "C:\Users\Admin\AppData\Roaming\Python\Python310\site-packages\nornir\core\task.py", line 174, in run
    raise NornirSubTaskError(task=run_task, result=r)
nornir.core.exceptions.NornirSubTaskError: Subtask: napalm_get (failed)


2022-02-17 13:40:23,903 -  nornir.core -     INFO -        run() - Running task 'Backup Device configurations' with args {'path': './data/configs'} on 1 hosts
2022-02-17 13:40:24,304 - nornir.core.task -    ERROR -      start() - Host 'host1': task 'napalm_get' failed with traceback:
Traceback (most recent call last):
  File "C:\Users\Admin\AppData\Roaming\Python\Python310\site-packages\paramiko\transport.py", line 2211, in _check_banner
    buf = self.packetizer.readline(timeout)
  File "C:\Users\Admin\AppData\Roaming\Python\Python310\site-packages\paramiko\packet.py", line 386, in readline
    return u(buf)
  File "C:\Users\Admin\AppData\Roaming\Python\Python310\site-packages\paramiko\py3compat.py", line 147, in u
    return s.decode(encoding)
UnicodeDecodeError: 'utf-8' codec can't decode byte 0xff in position 0: invalid start byte

During handling of the above exception, another exception occurred:

Traceback (most recent call last):
  File "C:\Users\Admin\AppData\Roaming\Python\Python310\site-packages\nornir\core\task.py", line 99, in start
    r = self.task(self, **self.params)
  File "C:\Users\Admin\AppData\Roaming\Python\Python310\site-packages\nornir_napalm\plugins\tasks\napalm_get.py", line 32, in napalm_get
    device = task.host.get_connection(CONNECTION_NAME, task.nornir.config)
  File "C:\Users\Admin\AppData\Roaming\Python\Python310\site-packages\nornir\core\inventory.py", line 494, in get_connection
    self.open_connection(
  File "C:\Users\Admin\AppData\Roaming\Python\Python310\site-packages\nornir\core\inventory.py", line 546, in open_connection
    conn_obj.open(
  File "C:\Users\Admin\AppData\Roaming\Python\Python310\site-packages\nornir_napalm\plugins\connections\__init__.py", line 57, in open
    connection.open()
  File "C:\Users\Admin\AppData\Roaming\Python\Python310\site-packages\napalm\ios\ios.py", line 169, in open
    self.device = self._netmiko_open(
  File "C:\Users\Admin\AppData\Roaming\Python\Python310\site-packages\napalm\base\base.py", line 86, in _netmiko_open
    self._netmiko_device = ConnectHandler(
  File "C:\Users\Admin\AppData\Roaming\Python\Python310\site-packages\netmiko\ssh_dispatcher.py", line 326, in ConnectHandler
    return ConnectionClass(*args, **kwargs)
  File "C:\Users\Admin\AppData\Roaming\Python\Python310\site-packages\netmiko\cisco\cisco_ios.py", line 17, in __init__
    return super().__init__(*args, **kwargs)
  File "C:\Users\Admin\AppData\Roaming\Python\Python310\site-packages\netmiko\base_connection.py", line 350, in __init__
    self._open()
  File "C:\Users\Admin\AppData\Roaming\Python\Python310\site-packages\netmiko\base_connection.py", line 355, in _open
    self.establish_connection()
  File "C:\Users\Admin\AppData\Roaming\Python\Python310\site-packages\netmiko\base_connection.py", line 935, in establish_connection
    self.remote_conn_pre.connect(**ssh_connect_params)
  File "C:\Users\Admin\AppData\Roaming\Python\Python310\site-packages\paramiko\client.py", line 406, in connect
    t.start_client(timeout=timeout)
  File "C:\Users\Admin\AppData\Roaming\Python\Python310\site-packages\paramiko\transport.py", line 660, in start_client
    raise e
  File "C:\Users\Admin\AppData\Roaming\Python\Python310\site-packages\paramiko\transport.py", line 2039, in run
    self._check_banner()
  File "C:\Users\Admin\AppData\Roaming\Python\Python310\site-packages\paramiko\transport.py", line 2215, in _check_banner
    raise SSHException(
paramiko.ssh_exception.SSHException: Error reading SSH protocol banner'utf-8' codec can't decode byte 0xff in position 0: invalid start byte

2022-02-17 13:40:24,306 - nornir.core.task -    ERROR -      start() - Host 'host1': task 'Backup Device configurations' failed with traceback:
Traceback (most recent call last):
  File "C:\Users\Admin\AppData\Roaming\Python\Python310\site-packages\nornir\core\task.py", line 99, in start
    r = self.task(self, **self.params)
  File "c:\Users\Admin\Documents\Code\Nornir\nornir\nornir_test.py", line 16, in backup_config
    device_config = task.run(task=napalm_get, getters=["get_config"])
  File "C:\Users\Admin\AppData\Roaming\Python\Python310\site-packages\nornir\core\task.py", line 174, in run
    raise NornirSubTaskError(task=run_task, result=r)
nornir.core.exceptions.NornirSubTaskError: Subtask: napalm_get (failed)


2022-02-17 13:45:08,881 -  nornir.core -     INFO -        run() - Running task 'Backup Device configurations' with args {'path': './data/configs'} on 1 hosts
2022-02-17 13:45:08,884 - nornir.core.task -    ERROR -      start() - Host 'host1': task 'napalm_get' failed with traceback:
Traceback (most recent call last):
  File "C:\Users\Admin\AppData\Roaming\Python\Python310\site-packages\nornir\core\task.py", line 99, in start
    r = self.task(self, **self.params)
  File "C:\Users\Admin\AppData\Roaming\Python\Python310\site-packages\nornir_napalm\plugins\tasks\napalm_get.py", line 32, in napalm_get
    device = task.host.get_connection(CONNECTION_NAME, task.nornir.config)
  File "C:\Users\Admin\AppData\Roaming\Python\Python310\site-packages\nornir\core\inventory.py", line 494, in get_connection
    self.open_connection(
  File "C:\Users\Admin\AppData\Roaming\Python\Python310\site-packages\nornir\core\inventory.py", line 546, in open_connection
    conn_obj.open(
  File "C:\Users\Admin\AppData\Roaming\Python\Python310\site-packages\nornir_napalm\plugins\connections\__init__.py", line 55, in open
    network_driver = get_network_driver(platform)
  File "C:\Users\Admin\AppData\Roaming\Python\Python310\site-packages\napalm\base\__init__.py", line 97, in get_network_driver
    raise ModuleImportError(
napalm.base.exceptions.ModuleImportError: Cannot import "cisco_ios_telnet". Is the library installed?

2022-02-17 13:45:08,884 - nornir.core.task -    ERROR -      start() - Host 'host1': task 'Backup Device configurations' failed with traceback:
Traceback (most recent call last):
  File "C:\Users\Admin\AppData\Roaming\Python\Python310\site-packages\nornir\core\task.py", line 99, in start
    r = self.task(self, **self.params)
  File "c:\Users\Admin\Documents\Code\Nornir\nornir\nornir_test.py", line 16, in backup_config
    device_config = task.run(task=napalm_get, getters=["get_config"])
  File "C:\Users\Admin\AppData\Roaming\Python\Python310\site-packages\nornir\core\task.py", line 174, in run
    raise NornirSubTaskError(task=run_task, result=r)
nornir.core.exceptions.NornirSubTaskError: Subtask: napalm_get (failed)


2022-02-17 13:46:35,566 -  nornir.core -     INFO -        run() - Running task 'Backup Device configurations' with args {'path': './data/configs'} on 1 hosts
2022-02-17 13:46:35,925 - nornir.core.task -    ERROR -      start() - Host 'host1': task 'napalm_get' failed with traceback:
Traceback (most recent call last):
  File "C:\Users\Admin\AppData\Roaming\Python\Python310\site-packages\paramiko\transport.py", line 2211, in _check_banner
    buf = self.packetizer.readline(timeout)
  File "C:\Users\Admin\AppData\Roaming\Python\Python310\site-packages\paramiko\packet.py", line 386, in readline
    return u(buf)
  File "C:\Users\Admin\AppData\Roaming\Python\Python310\site-packages\paramiko\py3compat.py", line 147, in u
    return s.decode(encoding)
UnicodeDecodeError: 'utf-8' codec can't decode byte 0xff in position 0: invalid start byte

During handling of the above exception, another exception occurred:

Traceback (most recent call last):
  File "C:\Users\Admin\AppData\Roaming\Python\Python310\site-packages\nornir\core\task.py", line 99, in start
    r = self.task(self, **self.params)
  File "C:\Users\Admin\AppData\Roaming\Python\Python310\site-packages\nornir_napalm\plugins\tasks\napalm_get.py", line 32, in napalm_get
    device = task.host.get_connection(CONNECTION_NAME, task.nornir.config)
  File "C:\Users\Admin\AppData\Roaming\Python\Python310\site-packages\nornir\core\inventory.py", line 494, in get_connection
    self.open_connection(
  File "C:\Users\Admin\AppData\Roaming\Python\Python310\site-packages\nornir\core\inventory.py", line 546, in open_connection
    conn_obj.open(
  File "C:\Users\Admin\AppData\Roaming\Python\Python310\site-packages\nornir_napalm\plugins\connections\__init__.py", line 57, in open
    connection.open()
  File "C:\Users\Admin\AppData\Roaming\Python\Python310\site-packages\napalm\ios\ios.py", line 169, in open
    self.device = self._netmiko_open(
  File "C:\Users\Admin\AppData\Roaming\Python\Python310\site-packages\napalm\base\base.py", line 86, in _netmiko_open
    self._netmiko_device = ConnectHandler(
  File "C:\Users\Admin\AppData\Roaming\Python\Python310\site-packages\netmiko\ssh_dispatcher.py", line 326, in ConnectHandler
    return ConnectionClass(*args, **kwargs)
  File "C:\Users\Admin\AppData\Roaming\Python\Python310\site-packages\netmiko\cisco\cisco_ios.py", line 17, in __init__
    return super().__init__(*args, **kwargs)
  File "C:\Users\Admin\AppData\Roaming\Python\Python310\site-packages\netmiko\base_connection.py", line 350, in __init__
    self._open()
  File "C:\Users\Admin\AppData\Roaming\Python\Python310\site-packages\netmiko\base_connection.py", line 355, in _open
    self.establish_connection()
  File "C:\Users\Admin\AppData\Roaming\Python\Python310\site-packages\netmiko\base_connection.py", line 935, in establish_connection
    self.remote_conn_pre.connect(**ssh_connect_params)
  File "C:\Users\Admin\AppData\Roaming\Python\Python310\site-packages\paramiko\client.py", line 406, in connect
    t.start_client(timeout=timeout)
  File "C:\Users\Admin\AppData\Roaming\Python\Python310\site-packages\paramiko\transport.py", line 660, in start_client
    raise e
  File "C:\Users\Admin\AppData\Roaming\Python\Python310\site-packages\paramiko\transport.py", line 2039, in run
    self._check_banner()
  File "C:\Users\Admin\AppData\Roaming\Python\Python310\site-packages\paramiko\transport.py", line 2215, in _check_banner
    raise SSHException(
paramiko.ssh_exception.SSHException: Error reading SSH protocol banner'utf-8' codec can't decode byte 0xff in position 0: invalid start byte

2022-02-17 13:46:35,927 - nornir.core.task -    ERROR -      start() - Host 'host1': task 'Backup Device configurations' failed with traceback:
Traceback (most recent call last):
  File "C:\Users\Admin\AppData\Roaming\Python\Python310\site-packages\nornir\core\task.py", line 99, in start
    r = self.task(self, **self.params)
  File "c:\Users\Admin\Documents\Code\Nornir\nornir\nornir_test.py", line 16, in backup_config
    device_config = task.run(task=napalm_get, getters=["get_config"])
  File "C:\Users\Admin\AppData\Roaming\Python\Python310\site-packages\nornir\core\task.py", line 174, in run
    raise NornirSubTaskError(task=run_task, result=r)
nornir.core.exceptions.NornirSubTaskError: Subtask: napalm_get (failed)


2022-02-17 13:49:22,127 -  nornir.core -     INFO -        run() - Running task 'Backup Device configurations' with args {'path': './data/configs'} on 1 hosts
2022-02-17 13:49:22,134 - nornir.core.task -    ERROR -      start() - Host 'host1': task 'napalm_get' failed with traceback:
Traceback (most recent call last):
  File "C:\Users\Admin\AppData\Roaming\Python\Python310\site-packages\paramiko\transport.py", line 2211, in _check_banner
    buf = self.packetizer.readline(timeout)
  File "C:\Users\Admin\AppData\Roaming\Python\Python310\site-packages\paramiko\packet.py", line 380, in readline
    buf += self._read_timeout(timeout)
  File "C:\Users\Admin\AppData\Roaming\Python\Python310\site-packages\paramiko\packet.py", line 607, in _read_timeout
    x = self.__socket.recv(128)
ConnectionResetError: [WinError 10054] An existing connection was forcibly closed by the remote host

During handling of the above exception, another exception occurred:

Traceback (most recent call last):
  File "C:\Users\Admin\AppData\Roaming\Python\Python310\site-packages\nornir\core\task.py", line 99, in start
    r = self.task(self, **self.params)
  File "C:\Users\Admin\AppData\Roaming\Python\Python310\site-packages\nornir_napalm\plugins\tasks\napalm_get.py", line 32, in napalm_get
    device = task.host.get_connection(CONNECTION_NAME, task.nornir.config)
  File "C:\Users\Admin\AppData\Roaming\Python\Python310\site-packages\nornir\core\inventory.py", line 494, in get_connection
    self.open_connection(
  File "C:\Users\Admin\AppData\Roaming\Python\Python310\site-packages\nornir\core\inventory.py", line 546, in open_connection
    conn_obj.open(
  File "C:\Users\Admin\AppData\Roaming\Python\Python310\site-packages\nornir_napalm\plugins\connections\__init__.py", line 57, in open
    connection.open()
  File "C:\Users\Admin\AppData\Roaming\Python\Python310\site-packages\napalm\ios\ios.py", line 169, in open
    self.device = self._netmiko_open(
  File "C:\Users\Admin\AppData\Roaming\Python\Python310\site-packages\napalm\base\base.py", line 86, in _netmiko_open
    self._netmiko_device = ConnectHandler(
  File "C:\Users\Admin\AppData\Roaming\Python\Python310\site-packages\netmiko\ssh_dispatcher.py", line 326, in ConnectHandler
    return ConnectionClass(*args, **kwargs)
  File "C:\Users\Admin\AppData\Roaming\Python\Python310\site-packages\netmiko\cisco\cisco_ios.py", line 17, in __init__
    return super().__init__(*args, **kwargs)
  File "C:\Users\Admin\AppData\Roaming\Python\Python310\site-packages\netmiko\base_connection.py", line 350, in __init__
    self._open()
  File "C:\Users\Admin\AppData\Roaming\Python\Python310\site-packages\netmiko\base_connection.py", line 355, in _open
    self.establish_connection()
  File "C:\Users\Admin\AppData\Roaming\Python\Python310\site-packages\netmiko\base_connection.py", line 935, in establish_connection
    self.remote_conn_pre.connect(**ssh_connect_params)
  File "C:\Users\Admin\AppData\Roaming\Python\Python310\site-packages\paramiko\client.py", line 406, in connect
    t.start_client(timeout=timeout)
  File "C:\Users\Admin\AppData\Roaming\Python\Python310\site-packages\paramiko\transport.py", line 660, in start_client
    raise e
  File "C:\Users\Admin\AppData\Roaming\Python\Python310\site-packages\paramiko\transport.py", line 2039, in run
    self._check_banner()
  File "C:\Users\Admin\AppData\Roaming\Python\Python310\site-packages\paramiko\transport.py", line 2215, in _check_banner
    raise SSHException(
paramiko.ssh_exception.SSHException: Error reading SSH protocol banner[WinError 10054] An existing connection was forcibly closed by the remote host

2022-02-17 13:49:22,134 - nornir.core.task -    ERROR -      start() - Host 'host1': task 'Backup Device configurations' failed with traceback:
Traceback (most recent call last):
  File "C:\Users\Admin\AppData\Roaming\Python\Python310\site-packages\nornir\core\task.py", line 99, in start
    r = self.task(self, **self.params)
  File "c:\Users\Admin\Documents\Code\Nornir\nornir\nornir_test.py", line 16, in backup_config
    device_config = task.run(task=napalm_get, getters=["get_config"])
  File "C:\Users\Admin\AppData\Roaming\Python\Python310\site-packages\nornir\core\task.py", line 174, in run
    raise NornirSubTaskError(task=run_task, result=r)
nornir.core.exceptions.NornirSubTaskError: Subtask: napalm_get (failed)


2022-02-17 13:49:46,754 -  nornir.core -     INFO -        run() - Running task 'Backup Device configurations' with args {'path': './data/configs'} on 1 hosts
2022-02-17 13:49:46,761 - nornir.core.task -    ERROR -      start() - Host 'host1': task 'napalm_get' failed with traceback:
Traceback (most recent call last):
  File "C:\Users\Admin\AppData\Roaming\Python\Python310\site-packages\paramiko\transport.py", line 2211, in _check_banner
    buf = self.packetizer.readline(timeout)
  File "C:\Users\Admin\AppData\Roaming\Python\Python310\site-packages\paramiko\packet.py", line 380, in readline
    buf += self._read_timeout(timeout)
  File "C:\Users\Admin\AppData\Roaming\Python\Python310\site-packages\paramiko\packet.py", line 607, in _read_timeout
    x = self.__socket.recv(128)
ConnectionAbortedError: [WinError 10053] An established connection was aborted by the software in your host machine

During handling of the above exception, another exception occurred:

Traceback (most recent call last):
  File "C:\Users\Admin\AppData\Roaming\Python\Python310\site-packages\nornir\core\task.py", line 99, in start
    r = self.task(self, **self.params)
  File "C:\Users\Admin\AppData\Roaming\Python\Python310\site-packages\nornir_napalm\plugins\tasks\napalm_get.py", line 32, in napalm_get
    device = task.host.get_connection(CONNECTION_NAME, task.nornir.config)
  File "C:\Users\Admin\AppData\Roaming\Python\Python310\site-packages\nornir\core\inventory.py", line 494, in get_connection
    self.open_connection(
  File "C:\Users\Admin\AppData\Roaming\Python\Python310\site-packages\nornir\core\inventory.py", line 546, in open_connection
    conn_obj.open(
  File "C:\Users\Admin\AppData\Roaming\Python\Python310\site-packages\nornir_napalm\plugins\connections\__init__.py", line 57, in open
    connection.open()
  File "C:\Users\Admin\AppData\Roaming\Python\Python310\site-packages\napalm\ios\ios.py", line 169, in open
    self.device = self._netmiko_open(
  File "C:\Users\Admin\AppData\Roaming\Python\Python310\site-packages\napalm\base\base.py", line 86, in _netmiko_open
    self._netmiko_device = ConnectHandler(
  File "C:\Users\Admin\AppData\Roaming\Python\Python310\site-packages\netmiko\ssh_dispatcher.py", line 326, in ConnectHandler
    return ConnectionClass(*args, **kwargs)
  File "C:\Users\Admin\AppData\Roaming\Python\Python310\site-packages\netmiko\cisco\cisco_ios.py", line 17, in __init__
    return super().__init__(*args, **kwargs)
  File "C:\Users\Admin\AppData\Roaming\Python\Python310\site-packages\netmiko\base_connection.py", line 350, in __init__
    self._open()
  File "C:\Users\Admin\AppData\Roaming\Python\Python310\site-packages\netmiko\base_connection.py", line 355, in _open
    self.establish_connection()
  File "C:\Users\Admin\AppData\Roaming\Python\Python310\site-packages\netmiko\base_connection.py", line 935, in establish_connection
    self.remote_conn_pre.connect(**ssh_connect_params)
  File "C:\Users\Admin\AppData\Roaming\Python\Python310\site-packages\paramiko\client.py", line 406, in connect
    t.start_client(timeout=timeout)
  File "C:\Users\Admin\AppData\Roaming\Python\Python310\site-packages\paramiko\transport.py", line 660, in start_client
    raise e
  File "C:\Users\Admin\AppData\Roaming\Python\Python310\site-packages\paramiko\transport.py", line 2039, in run
    self._check_banner()
  File "C:\Users\Admin\AppData\Roaming\Python\Python310\site-packages\paramiko\transport.py", line 2215, in _check_banner
    raise SSHException(
paramiko.ssh_exception.SSHException: Error reading SSH protocol banner[WinError 10053] An established connection was aborted by the software in your host machine

2022-02-17 13:49:46,762 - nornir.core.task -    ERROR -      start() - Host 'host1': task 'Backup Device configurations' failed with traceback:
Traceback (most recent call last):
  File "C:\Users\Admin\AppData\Roaming\Python\Python310\site-packages\nornir\core\task.py", line 99, in start
    r = self.task(self, **self.params)
  File "c:\Users\Admin\Documents\Code\Nornir\nornir\nornir_test.py", line 16, in backup_config
    device_config = task.run(task=napalm_get, getters=["get_config"])
  File "C:\Users\Admin\AppData\Roaming\Python\Python310\site-packages\nornir\core\task.py", line 174, in run
    raise NornirSubTaskError(task=run_task, result=r)
nornir.core.exceptions.NornirSubTaskError: Subtask: napalm_get (failed)


2022-02-17 13:50:47,700 -  nornir.core -     INFO -        run() - Running task 'Backup Device configurations' with args {'path': './data/configs'} on 1 hosts
2022-02-17 13:50:48,496 - nornir.core.task -    ERROR -      start() - Host 'host1': task 'napalm_get' failed with traceback:
Traceback (most recent call last):
  File "C:\Users\Admin\AppData\Roaming\Python\Python310\site-packages\paramiko\transport.py", line 2211, in _check_banner
    buf = self.packetizer.readline(timeout)
  File "C:\Users\Admin\AppData\Roaming\Python\Python310\site-packages\paramiko\packet.py", line 386, in readline
    return u(buf)
  File "C:\Users\Admin\AppData\Roaming\Python\Python310\site-packages\paramiko\py3compat.py", line 147, in u
    return s.decode(encoding)
UnicodeDecodeError: 'utf-8' codec can't decode byte 0xff in position 0: invalid start byte

During handling of the above exception, another exception occurred:

Traceback (most recent call last):
  File "C:\Users\Admin\AppData\Roaming\Python\Python310\site-packages\nornir\core\task.py", line 99, in start
    r = self.task(self, **self.params)
  File "C:\Users\Admin\AppData\Roaming\Python\Python310\site-packages\nornir_napalm\plugins\tasks\napalm_get.py", line 32, in napalm_get
    device = task.host.get_connection(CONNECTION_NAME, task.nornir.config)
  File "C:\Users\Admin\AppData\Roaming\Python\Python310\site-packages\nornir\core\inventory.py", line 494, in get_connection
    self.open_connection(
  File "C:\Users\Admin\AppData\Roaming\Python\Python310\site-packages\nornir\core\inventory.py", line 546, in open_connection
    conn_obj.open(
  File "C:\Users\Admin\AppData\Roaming\Python\Python310\site-packages\nornir_napalm\plugins\connections\__init__.py", line 57, in open
    connection.open()
  File "C:\Users\Admin\AppData\Roaming\Python\Python310\site-packages\napalm\ios\ios.py", line 169, in open
    self.device = self._netmiko_open(
  File "C:\Users\Admin\AppData\Roaming\Python\Python310\site-packages\napalm\base\base.py", line 86, in _netmiko_open
    self._netmiko_device = ConnectHandler(
  File "C:\Users\Admin\AppData\Roaming\Python\Python310\site-packages\netmiko\ssh_dispatcher.py", line 326, in ConnectHandler
    return ConnectionClass(*args, **kwargs)
  File "C:\Users\Admin\AppData\Roaming\Python\Python310\site-packages\netmiko\cisco\cisco_ios.py", line 17, in __init__
    return super().__init__(*args, **kwargs)
  File "C:\Users\Admin\AppData\Roaming\Python\Python310\site-packages\netmiko\base_connection.py", line 350, in __init__
    self._open()
  File "C:\Users\Admin\AppData\Roaming\Python\Python310\site-packages\netmiko\base_connection.py", line 355, in _open
    self.establish_connection()
  File "C:\Users\Admin\AppData\Roaming\Python\Python310\site-packages\netmiko\base_connection.py", line 935, in establish_connection
    self.remote_conn_pre.connect(**ssh_connect_params)
  File "C:\Users\Admin\AppData\Roaming\Python\Python310\site-packages\paramiko\client.py", line 406, in connect
    t.start_client(timeout=timeout)
  File "C:\Users\Admin\AppData\Roaming\Python\Python310\site-packages\paramiko\transport.py", line 660, in start_client
    raise e
  File "C:\Users\Admin\AppData\Roaming\Python\Python310\site-packages\paramiko\transport.py", line 2039, in run
    self._check_banner()
  File "C:\Users\Admin\AppData\Roaming\Python\Python310\site-packages\paramiko\transport.py", line 2215, in _check_banner
    raise SSHException(
paramiko.ssh_exception.SSHException: Error reading SSH protocol banner'utf-8' codec can't decode byte 0xff in position 0: invalid start byte

2022-02-17 13:50:48,496 - nornir.core.task -    ERROR -      start() - Host 'host1': task 'Backup Device configurations' failed with traceback:
Traceback (most recent call last):
  File "C:\Users\Admin\AppData\Roaming\Python\Python310\site-packages\nornir\core\task.py", line 99, in start
    r = self.task(self, **self.params)
  File "c:\Users\Admin\Documents\Code\Nornir\nornir\nornir_test.py", line 16, in backup_config
    device_config = task.run(task=napalm_get, getters=["get_config"])
  File "C:\Users\Admin\AppData\Roaming\Python\Python310\site-packages\nornir\core\task.py", line 174, in run
    raise NornirSubTaskError(task=run_task, result=r)
nornir.core.exceptions.NornirSubTaskError: Subtask: napalm_get (failed)


2022-02-17 13:54:41,653 -  nornir.core -     INFO -        run() - Running task 'Backup Device configurations' with args {'path': './data/configs'} on 1 hosts
2022-02-17 13:54:42,047 - nornir.core.task -    ERROR -      start() - Host 'host1': task 'napalm_get' failed with traceback:
Traceback (most recent call last):
  File "C:\Users\Admin\AppData\Roaming\Python\Python310\site-packages\paramiko\transport.py", line 2211, in _check_banner
    buf = self.packetizer.readline(timeout)
  File "C:\Users\Admin\AppData\Roaming\Python\Python310\site-packages\paramiko\packet.py", line 386, in readline
    return u(buf)
  File "C:\Users\Admin\AppData\Roaming\Python\Python310\site-packages\paramiko\py3compat.py", line 147, in u
    return s.decode(encoding)
UnicodeDecodeError: 'utf-8' codec can't decode byte 0xff in position 0: invalid start byte

During handling of the above exception, another exception occurred:

Traceback (most recent call last):
  File "C:\Users\Admin\AppData\Roaming\Python\Python310\site-packages\nornir\core\task.py", line 99, in start
    r = self.task(self, **self.params)
  File "C:\Users\Admin\AppData\Roaming\Python\Python310\site-packages\nornir_napalm\plugins\tasks\napalm_get.py", line 32, in napalm_get
    device = task.host.get_connection(CONNECTION_NAME, task.nornir.config)
  File "C:\Users\Admin\AppData\Roaming\Python\Python310\site-packages\nornir\core\inventory.py", line 494, in get_connection
    self.open_connection(
  File "C:\Users\Admin\AppData\Roaming\Python\Python310\site-packages\nornir\core\inventory.py", line 546, in open_connection
    conn_obj.open(
  File "C:\Users\Admin\AppData\Roaming\Python\Python310\site-packages\nornir_napalm\plugins\connections\__init__.py", line 57, in open
    connection.open()
  File "C:\Users\Admin\AppData\Roaming\Python\Python310\site-packages\napalm\ios\ios.py", line 169, in open
    self.device = self._netmiko_open(
  File "C:\Users\Admin\AppData\Roaming\Python\Python310\site-packages\napalm\base\base.py", line 86, in _netmiko_open
    self._netmiko_device = ConnectHandler(
  File "C:\Users\Admin\AppData\Roaming\Python\Python310\site-packages\netmiko\ssh_dispatcher.py", line 326, in ConnectHandler
    return ConnectionClass(*args, **kwargs)
  File "C:\Users\Admin\AppData\Roaming\Python\Python310\site-packages\netmiko\cisco\cisco_ios.py", line 17, in __init__
    return super().__init__(*args, **kwargs)
  File "C:\Users\Admin\AppData\Roaming\Python\Python310\site-packages\netmiko\base_connection.py", line 350, in __init__
    self._open()
  File "C:\Users\Admin\AppData\Roaming\Python\Python310\site-packages\netmiko\base_connection.py", line 355, in _open
    self.establish_connection()
  File "C:\Users\Admin\AppData\Roaming\Python\Python310\site-packages\netmiko\base_connection.py", line 935, in establish_connection
    self.remote_conn_pre.connect(**ssh_connect_params)
  File "C:\Users\Admin\AppData\Roaming\Python\Python310\site-packages\paramiko\client.py", line 406, in connect
    t.start_client(timeout=timeout)
  File "C:\Users\Admin\AppData\Roaming\Python\Python310\site-packages\paramiko\transport.py", line 660, in start_client
    raise e
  File "C:\Users\Admin\AppData\Roaming\Python\Python310\site-packages\paramiko\transport.py", line 2039, in run
    self._check_banner()
  File "C:\Users\Admin\AppData\Roaming\Python\Python310\site-packages\paramiko\transport.py", line 2215, in _check_banner
    raise SSHException(
paramiko.ssh_exception.SSHException: Error reading SSH protocol banner'utf-8' codec can't decode byte 0xff in position 0: invalid start byte

2022-02-17 13:54:42,048 - nornir.core.task -    ERROR -      start() - Host 'host1': task 'Backup Device configurations' failed with traceback:
Traceback (most recent call last):
  File "C:\Users\Admin\AppData\Roaming\Python\Python310\site-packages\nornir\core\task.py", line 99, in start
    r = self.task(self, **self.params)
  File "c:\Users\Admin\Documents\Code\Nornir\nornir\nornir_test.py", line 16, in backup_config
    device_config = task.run(task=napalm_get, getters=["get_config"])
  File "C:\Users\Admin\AppData\Roaming\Python\Python310\site-packages\nornir\core\task.py", line 174, in run
    raise NornirSubTaskError(task=run_task, result=r)
nornir.core.exceptions.NornirSubTaskError: Subtask: napalm_get (failed)


2022-02-17 14:04:16,817 -  nornir.core -     INFO -        run() - Running task 'Backup Device configurations' with args {'path': './data/configs'} on 1 hosts
2022-02-17 14:04:16,819 - nornir.core.task -    ERROR -      start() - Host 'host1': task 'napalm_get' failed with traceback:
Traceback (most recent call last):
  File "C:\Users\Admin\AppData\Roaming\Python\Python310\site-packages\nornir\core\task.py", line 99, in start
    r = self.task(self, **self.params)
  File "C:\Users\Admin\AppData\Roaming\Python\Python310\site-packages\nornir_napalm\plugins\tasks\napalm_get.py", line 32, in napalm_get
    device = task.host.get_connection(CONNECTION_NAME, task.nornir.config)
  File "C:\Users\Admin\AppData\Roaming\Python\Python310\site-packages\nornir\core\inventory.py", line 494, in get_connection
    self.open_connection(
  File "C:\Users\Admin\AppData\Roaming\Python\Python310\site-packages\nornir\core\inventory.py", line 546, in open_connection
    conn_obj.open(
  File "C:\Users\Admin\AppData\Roaming\Python\Python310\site-packages\nornir_napalm\plugins\connections\__init__.py", line 55, in open
    network_driver = get_network_driver(platform)
  File "C:\Users\Admin\AppData\Roaming\Python\Python310\site-packages\napalm\base\__init__.py", line 97, in get_network_driver
    raise ModuleImportError(
napalm.base.exceptions.ModuleImportError: Cannot import "ciscoiostelnet". Is the library installed?

2022-02-17 14:04:16,820 - nornir.core.task -    ERROR -      start() - Host 'host1': task 'Backup Device configurations' failed with traceback:
Traceback (most recent call last):
  File "C:\Users\Admin\AppData\Roaming\Python\Python310\site-packages\nornir\core\task.py", line 99, in start
    r = self.task(self, **self.params)
  File "c:\Users\Admin\Documents\Code\Nornir\nornir\nornir_test.py", line 16, in backup_config
    device_config = task.run(task=napalm_get, getters=["get_config"])
  File "C:\Users\Admin\AppData\Roaming\Python\Python310\site-packages\nornir\core\task.py", line 174, in run
    raise NornirSubTaskError(task=run_task, result=r)
nornir.core.exceptions.NornirSubTaskError: Subtask: napalm_get (failed)


2022-02-17 14:08:05,941 -  nornir.core -     INFO -        run() - Running task 'Backup Device configurations' with args {'path': './data/configs'} on 1 hosts
2022-02-17 14:08:05,943 - nornir.core.task -    ERROR -      start() - Host 'host1': task 'napalm_get' failed with traceback:
Traceback (most recent call last):
  File "C:\Users\Admin\AppData\Roaming\Python\Python310\site-packages\nornir\core\task.py", line 99, in start
    r = self.task(self, **self.params)
  File "C:\Users\Admin\AppData\Roaming\Python\Python310\site-packages\nornir_napalm\plugins\tasks\napalm_get.py", line 32, in napalm_get
    device = task.host.get_connection(CONNECTION_NAME, task.nornir.config)
  File "C:\Users\Admin\AppData\Roaming\Python\Python310\site-packages\nornir\core\inventory.py", line 494, in get_connection
    self.open_connection(
  File "C:\Users\Admin\AppData\Roaming\Python\Python310\site-packages\nornir\core\inventory.py", line 546, in open_connection
    conn_obj.open(
  File "C:\Users\Admin\AppData\Roaming\Python\Python310\site-packages\nornir_napalm\plugins\connections\__init__.py", line 55, in open
    network_driver = get_network_driver(platform)
  File "C:\Users\Admin\AppData\Roaming\Python\Python310\site-packages\napalm\base\__init__.py", line 68, in get_network_driver
    raise ModuleImportError("Please provide a valid driver name.")
napalm.base.exceptions.ModuleImportError: Please provide a valid driver name.

2022-02-17 14:08:05,943 - nornir.core.task -    ERROR -      start() - Host 'host1': task 'Backup Device configurations' failed with traceback:
Traceback (most recent call last):
  File "C:\Users\Admin\AppData\Roaming\Python\Python310\site-packages\nornir\core\task.py", line 99, in start
    r = self.task(self, **self.params)
  File "c:\Users\Admin\Documents\Code\Nornir\nornir\nornir_test.py", line 16, in backup_config
    device_config = task.run(task=napalm_get, getters=["get_config"])
  File "C:\Users\Admin\AppData\Roaming\Python\Python310\site-packages\nornir\core\task.py", line 174, in run
    raise NornirSubTaskError(task=run_task, result=r)
nornir.core.exceptions.NornirSubTaskError: Subtask: napalm_get (failed)


2022-02-17 14:08:44,767 -  nornir.core -     INFO -        run() - Running task 'Backup Device configurations' with args {'path': './data/configs'} on 1 hosts
2022-02-17 14:08:49,804 - nornir.core.task -    ERROR -      start() - Host 'host1': task 'napalm_get' failed with traceback:
Traceback (most recent call last):
  File "C:\Users\Admin\AppData\Roaming\Python\Python310\site-packages\netmiko\base_connection.py", line 935, in establish_connection
    self.remote_conn_pre.connect(**ssh_connect_params)
  File "C:\Users\Admin\AppData\Roaming\Python\Python310\site-packages\paramiko\client.py", line 412, in connect
    server_key = t.get_remote_server_key()
  File "C:\Users\Admin\AppData\Roaming\Python\Python310\site-packages\paramiko\transport.py", line 834, in get_remote_server_key
    raise SSHException("No existing session")
paramiko.ssh_exception.SSHException: No existing session

During handling of the above exception, another exception occurred:

Traceback (most recent call last):
  File "C:\Users\Admin\AppData\Roaming\Python\Python310\site-packages\napalm\base\base.py", line 86, in _netmiko_open
    self._netmiko_device = ConnectHandler(
  File "C:\Users\Admin\AppData\Roaming\Python\Python310\site-packages\netmiko\ssh_dispatcher.py", line 326, in ConnectHandler
    return ConnectionClass(*args, **kwargs)
  File "C:\Users\Admin\AppData\Roaming\Python\Python310\site-packages\netmiko\cisco\cisco_ios.py", line 17, in __init__
    return super().__init__(*args, **kwargs)
  File "C:\Users\Admin\AppData\Roaming\Python\Python310\site-packages\netmiko\base_connection.py", line 350, in __init__
    self._open()
  File "C:\Users\Admin\AppData\Roaming\Python\Python310\site-packages\netmiko\base_connection.py", line 355, in _open
    self.establish_connection()
  File "C:\Users\Admin\AppData\Roaming\Python\Python310\site-packages\netmiko\base_connection.py", line 980, in establish_connection
    raise NetmikoTimeoutException(msg)
netmiko.ssh_exception.NetmikoTimeoutException: Paramiko: 'No existing session' error: try increasing 'conn_timeout' to 10 seconds or larger.

During handling of the above exception, another exception occurred:

Traceback (most recent call last):
  File "C:\Users\Admin\AppData\Roaming\Python\Python310\site-packages\nornir\core\task.py", line 99, in start
    r = self.task(self, **self.params)
  File "C:\Users\Admin\AppData\Roaming\Python\Python310\site-packages\nornir_napalm\plugins\tasks\napalm_get.py", line 32, in napalm_get
    device = task.host.get_connection(CONNECTION_NAME, task.nornir.config)
  File "C:\Users\Admin\AppData\Roaming\Python\Python310\site-packages\nornir\core\inventory.py", line 494, in get_connection
    self.open_connection(
  File "C:\Users\Admin\AppData\Roaming\Python\Python310\site-packages\nornir\core\inventory.py", line 546, in open_connection
    conn_obj.open(
  File "C:\Users\Admin\AppData\Roaming\Python\Python310\site-packages\nornir_napalm\plugins\connections\__init__.py", line 57, in open
    connection.open()
  File "C:\Users\Admin\AppData\Roaming\Python\Python310\site-packages\napalm\ios\ios.py", line 169, in open
    self.device = self._netmiko_open(
  File "C:\Users\Admin\AppData\Roaming\Python\Python310\site-packages\napalm\base\base.py", line 95, in _netmiko_open
    raise ConnectionException("Cannot connect to {}".format(self.hostname))
napalm.base.exceptions.ConnectionException: Cannot connect to 127.0.0.1

2022-02-17 14:08:49,809 - nornir.core.task -    ERROR -      start() - Host 'host1': task 'Backup Device configurations' failed with traceback:
Traceback (most recent call last):
  File "C:\Users\Admin\AppData\Roaming\Python\Python310\site-packages\nornir\core\task.py", line 99, in start
    r = self.task(self, **self.params)
  File "c:\Users\Admin\Documents\Code\Nornir\nornir\nornir_test.py", line 16, in backup_config
    device_config = task.run(task=napalm_get, getters=["get_config"])
  File "C:\Users\Admin\AppData\Roaming\Python\Python310\site-packages\nornir\core\task.py", line 174, in run
    raise NornirSubTaskError(task=run_task, result=r)
nornir.core.exceptions.NornirSubTaskError: Subtask: napalm_get (failed)


2022-02-17 14:09:48,333 -  nornir.core -     INFO -        run() - Running task 'Backup Device configurations' with args {'path': './data/configs'} on 1 hosts
2022-02-17 14:09:48,881 - nornir.core.task -    ERROR -      start() - Host 'host1': task 'napalm_get' failed with traceback:
Traceback (most recent call last):
  File "C:\Users\Admin\AppData\Roaming\Python\Python310\site-packages\paramiko\transport.py", line 2211, in _check_banner
    buf = self.packetizer.readline(timeout)
  File "C:\Users\Admin\AppData\Roaming\Python\Python310\site-packages\paramiko\packet.py", line 386, in readline
    return u(buf)
  File "C:\Users\Admin\AppData\Roaming\Python\Python310\site-packages\paramiko\py3compat.py", line 147, in u
    return s.decode(encoding)
UnicodeDecodeError: 'utf-8' codec can't decode byte 0xff in position 0: invalid start byte

During handling of the above exception, another exception occurred:

Traceback (most recent call last):
  File "C:\Users\Admin\AppData\Roaming\Python\Python310\site-packages\nornir\core\task.py", line 99, in start
    r = self.task(self, **self.params)
  File "C:\Users\Admin\AppData\Roaming\Python\Python310\site-packages\nornir_napalm\plugins\tasks\napalm_get.py", line 32, in napalm_get
    device = task.host.get_connection(CONNECTION_NAME, task.nornir.config)
  File "C:\Users\Admin\AppData\Roaming\Python\Python310\site-packages\nornir\core\inventory.py", line 494, in get_connection
    self.open_connection(
  File "C:\Users\Admin\AppData\Roaming\Python\Python310\site-packages\nornir\core\inventory.py", line 546, in open_connection
    conn_obj.open(
  File "C:\Users\Admin\AppData\Roaming\Python\Python310\site-packages\nornir_napalm\plugins\connections\__init__.py", line 57, in open
    connection.open()
  File "C:\Users\Admin\AppData\Roaming\Python\Python310\site-packages\napalm\ios\ios.py", line 169, in open
    self.device = self._netmiko_open(
  File "C:\Users\Admin\AppData\Roaming\Python\Python310\site-packages\napalm\base\base.py", line 86, in _netmiko_open
    self._netmiko_device = ConnectHandler(
  File "C:\Users\Admin\AppData\Roaming\Python\Python310\site-packages\netmiko\ssh_dispatcher.py", line 326, in ConnectHandler
    return ConnectionClass(*args, **kwargs)
  File "C:\Users\Admin\AppData\Roaming\Python\Python310\site-packages\netmiko\cisco\cisco_ios.py", line 17, in __init__
    return super().__init__(*args, **kwargs)
  File "C:\Users\Admin\AppData\Roaming\Python\Python310\site-packages\netmiko\base_connection.py", line 350, in __init__
    self._open()
  File "C:\Users\Admin\AppData\Roaming\Python\Python310\site-packages\netmiko\base_connection.py", line 355, in _open
    self.establish_connection()
  File "C:\Users\Admin\AppData\Roaming\Python\Python310\site-packages\netmiko\base_connection.py", line 935, in establish_connection
    self.remote_conn_pre.connect(**ssh_connect_params)
  File "C:\Users\Admin\AppData\Roaming\Python\Python310\site-packages\paramiko\client.py", line 406, in connect
    t.start_client(timeout=timeout)
  File "C:\Users\Admin\AppData\Roaming\Python\Python310\site-packages\paramiko\transport.py", line 660, in start_client
    raise e
  File "C:\Users\Admin\AppData\Roaming\Python\Python310\site-packages\paramiko\transport.py", line 2039, in run
    self._check_banner()
  File "C:\Users\Admin\AppData\Roaming\Python\Python310\site-packages\paramiko\transport.py", line 2215, in _check_banner
    raise SSHException(
paramiko.ssh_exception.SSHException: Error reading SSH protocol banner'utf-8' codec can't decode byte 0xff in position 0: invalid start byte

2022-02-17 14:09:48,882 - nornir.core.task -    ERROR -      start() - Host 'host1': task 'Backup Device configurations' failed with traceback:
Traceback (most recent call last):
  File "C:\Users\Admin\AppData\Roaming\Python\Python310\site-packages\nornir\core\task.py", line 99, in start
    r = self.task(self, **self.params)
  File "c:\Users\Admin\Documents\Code\Nornir\nornir\nornir_test.py", line 16, in backup_config
    device_config = task.run(task=napalm_get, getters=["get_config"])
  File "C:\Users\Admin\AppData\Roaming\Python\Python310\site-packages\nornir\core\task.py", line 174, in run
    raise NornirSubTaskError(task=run_task, result=r)
nornir.core.exceptions.NornirSubTaskError: Subtask: napalm_get (failed)


2022-02-17 14:10:19,358 -  nornir.core -     INFO -        run() - Running task 'Backup Device configurations' with args {'path': './data/configs'} on 1 hosts
2022-02-17 14:10:19,706 - nornir.core.task -    ERROR -      start() - Host 'host1': task 'napalm_get' failed with traceback:
Traceback (most recent call last):
  File "C:\Users\Admin\AppData\Roaming\Python\Python310\site-packages\paramiko\transport.py", line 2211, in _check_banner
    buf = self.packetizer.readline(timeout)
  File "C:\Users\Admin\AppData\Roaming\Python\Python310\site-packages\paramiko\packet.py", line 386, in readline
    return u(buf)
  File "C:\Users\Admin\AppData\Roaming\Python\Python310\site-packages\paramiko\py3compat.py", line 147, in u
    return s.decode(encoding)
UnicodeDecodeError: 'utf-8' codec can't decode byte 0xff in position 0: invalid start byte

During handling of the above exception, another exception occurred:

Traceback (most recent call last):
  File "C:\Users\Admin\AppData\Roaming\Python\Python310\site-packages\nornir\core\task.py", line 99, in start
    r = self.task(self, **self.params)
  File "C:\Users\Admin\AppData\Roaming\Python\Python310\site-packages\nornir_napalm\plugins\tasks\napalm_get.py", line 32, in napalm_get
    device = task.host.get_connection(CONNECTION_NAME, task.nornir.config)
  File "C:\Users\Admin\AppData\Roaming\Python\Python310\site-packages\nornir\core\inventory.py", line 494, in get_connection
    self.open_connection(
  File "C:\Users\Admin\AppData\Roaming\Python\Python310\site-packages\nornir\core\inventory.py", line 546, in open_connection
    conn_obj.open(
  File "C:\Users\Admin\AppData\Roaming\Python\Python310\site-packages\nornir_napalm\plugins\connections\__init__.py", line 57, in open
    connection.open()
  File "C:\Users\Admin\AppData\Roaming\Python\Python310\site-packages\napalm\ios\ios.py", line 169, in open
    self.device = self._netmiko_open(
  File "C:\Users\Admin\AppData\Roaming\Python\Python310\site-packages\napalm\base\base.py", line 86, in _netmiko_open
    self._netmiko_device = ConnectHandler(
  File "C:\Users\Admin\AppData\Roaming\Python\Python310\site-packages\netmiko\ssh_dispatcher.py", line 326, in ConnectHandler
    return ConnectionClass(*args, **kwargs)
  File "C:\Users\Admin\AppData\Roaming\Python\Python310\site-packages\netmiko\cisco\cisco_ios.py", line 17, in __init__
    return super().__init__(*args, **kwargs)
  File "C:\Users\Admin\AppData\Roaming\Python\Python310\site-packages\netmiko\base_connection.py", line 350, in __init__
    self._open()
  File "C:\Users\Admin\AppData\Roaming\Python\Python310\site-packages\netmiko\base_connection.py", line 355, in _open
    self.establish_connection()
  File "C:\Users\Admin\AppData\Roaming\Python\Python310\site-packages\netmiko\base_connection.py", line 935, in establish_connection
    self.remote_conn_pre.connect(**ssh_connect_params)
  File "C:\Users\Admin\AppData\Roaming\Python\Python310\site-packages\paramiko\client.py", line 406, in connect
    t.start_client(timeout=timeout)
  File "C:\Users\Admin\AppData\Roaming\Python\Python310\site-packages\paramiko\transport.py", line 660, in start_client
    raise e
  File "C:\Users\Admin\AppData\Roaming\Python\Python310\site-packages\paramiko\transport.py", line 2039, in run
    self._check_banner()
  File "C:\Users\Admin\AppData\Roaming\Python\Python310\site-packages\paramiko\transport.py", line 2215, in _check_banner
    raise SSHException(
paramiko.ssh_exception.SSHException: Error reading SSH protocol banner'utf-8' codec can't decode byte 0xff in position 0: invalid start byte

2022-02-17 14:10:19,706 - nornir.core.task -    ERROR -      start() - Host 'host1': task 'Backup Device configurations' failed with traceback:
Traceback (most recent call last):
  File "C:\Users\Admin\AppData\Roaming\Python\Python310\site-packages\nornir\core\task.py", line 99, in start
    r = self.task(self, **self.params)
  File "c:\Users\Admin\Documents\Code\Nornir\nornir\nornir_test.py", line 16, in backup_config
    device_config = task.run(task=napalm_get, getters=["get_config"])
  File "C:\Users\Admin\AppData\Roaming\Python\Python310\site-packages\nornir\core\task.py", line 174, in run
    raise NornirSubTaskError(task=run_task, result=r)
nornir.core.exceptions.NornirSubTaskError: Subtask: napalm_get (failed)


