2022-02-17 17:56:36,026 -  nornir.core -     INFO -        run() - Running task 'Backup Device configurations' with args {'path': './data/configs'} on 1 hosts
2022-02-17 17:56:41,040 - nornir.core.task -    ERROR -      start() - Host 'host1': task 'napalm_get' failed with traceback:
Traceback (most recent call last):
  File "C:\Users\micha\AppData\Roaming\Python\Python310\site-packages\netmiko\base_connection.py", line 935, in establish_connection
    self.remote_conn_pre.connect(**ssh_connect_params)
  File "C:\Users\micha\AppData\Roaming\Python\Python310\site-packages\paramiko\client.py", line 412, in connect
    server_key = t.get_remote_server_key()
  File "C:\Users\micha\AppData\Roaming\Python\Python310\site-packages\paramiko\transport.py", line 834, in get_remote_server_key
    raise SSHException("No existing session")
paramiko.ssh_exception.SSHException: No existing session

During handling of the above exception, another exception occurred:

Traceback (most recent call last):
  File "C:\Users\micha\AppData\Roaming\Python\Python310\site-packages\napalm\base\base.py", line 86, in _netmiko_open
    self._netmiko_device = ConnectHandler(
  File "C:\Users\micha\AppData\Roaming\Python\Python310\site-packages\netmiko\ssh_dispatcher.py", line 326, in ConnectHandler
    return ConnectionClass(*args, **kwargs)
  File "C:\Users\micha\AppData\Roaming\Python\Python310\site-packages\netmiko\cisco\cisco_ios.py", line 17, in __init__
    return super().__init__(*args, **kwargs)
  File "C:\Users\micha\AppData\Roaming\Python\Python310\site-packages\netmiko\base_connection.py", line 350, in __init__
    self._open()
  File "C:\Users\micha\AppData\Roaming\Python\Python310\site-packages\netmiko\base_connection.py", line 355, in _open
    self.establish_connection()
  File "C:\Users\micha\AppData\Roaming\Python\Python310\site-packages\netmiko\base_connection.py", line 980, in establish_connection
    raise NetmikoTimeoutException(msg)
netmiko.ssh_exception.NetmikoTimeoutException: Paramiko: 'No existing session' error: try increasing 'conn_timeout' to 10 seconds or larger.

During handling of the above exception, another exception occurred:

Traceback (most recent call last):
  File "C:\Users\micha\AppData\Roaming\Python\Python310\site-packages\nornir\core\task.py", line 99, in start
    r = self.task(self, **self.params)
  File "C:\Users\micha\AppData\Roaming\Python\Python310\site-packages\nornir_napalm\plugins\tasks\napalm_get.py", line 32, in napalm_get
    device = task.host.get_connection(CONNECTION_NAME, task.nornir.config)
  File "C:\Users\micha\AppData\Roaming\Python\Python310\site-packages\nornir\core\inventory.py", line 494, in get_connection
    self.open_connection(
  File "C:\Users\micha\AppData\Roaming\Python\Python310\site-packages\nornir\core\inventory.py", line 546, in open_connection
    conn_obj.open(
  File "C:\Users\micha\AppData\Roaming\Python\Python310\site-packages\nornir_napalm\plugins\connections\__init__.py", line 57, in open
    connection.open()
  File "C:\Users\micha\AppData\Roaming\Python\Python310\site-packages\napalm\ios\ios.py", line 169, in open
    self.device = self._netmiko_open(
  File "C:\Users\micha\AppData\Roaming\Python\Python310\site-packages\napalm\base\base.py", line 95, in _netmiko_open
    raise ConnectionException("Cannot connect to {}".format(self.hostname))
napalm.base.exceptions.ConnectionException: Cannot connect to 127.0.0.1

2022-02-17 17:56:41,041 - nornir.core.task -    ERROR -      start() - Host 'host1': task 'Backup Device configurations' failed with traceback:
Traceback (most recent call last):
  File "C:\Users\micha\AppData\Roaming\Python\Python310\site-packages\nornir\core\task.py", line 99, in start
    r = self.task(self, **self.params)
  File "c:\Users\micha\OneDrive\Documents\Code Repo\nornir\nornir_test.py", line 16, in backup_config
    device_config = task.run(task=napalm_get, getters=["get_config"])
  File "C:\Users\micha\AppData\Roaming\Python\Python310\site-packages\nornir\core\task.py", line 174, in run
    raise NornirSubTaskError(task=run_task, result=r)
nornir.core.exceptions.NornirSubTaskError: Subtask: napalm_get (failed)


2022-02-17 17:59:55,282 -  nornir.core -     INFO -        run() - Running task 'Backup Device configurations' with args {'path': './data/configs'} on 1 hosts
2022-02-17 17:59:55,532 - nornir.core.task -    ERROR -      start() - Host 'host1': task 'napalm_get' failed with traceback:
Traceback (most recent call last):
  File "C:\Users\micha\AppData\Roaming\Python\Python310\site-packages\paramiko\transport.py", line 2211, in _check_banner
    buf = self.packetizer.readline(timeout)
  File "C:\Users\micha\AppData\Roaming\Python\Python310\site-packages\paramiko\packet.py", line 386, in readline
    return u(buf)
  File "C:\Users\micha\AppData\Roaming\Python\Python310\site-packages\paramiko\py3compat.py", line 147, in u
    return s.decode(encoding)
UnicodeDecodeError: 'utf-8' codec can't decode byte 0xff in position 0: invalid start byte

During handling of the above exception, another exception occurred:

Traceback (most recent call last):
  File "C:\Users\micha\AppData\Roaming\Python\Python310\site-packages\nornir\core\task.py", line 99, in start
    r = self.task(self, **self.params)
  File "C:\Users\micha\AppData\Roaming\Python\Python310\site-packages\nornir_napalm\plugins\tasks\napalm_get.py", line 32, in napalm_get
    device = task.host.get_connection(CONNECTION_NAME, task.nornir.config)
  File "C:\Users\micha\AppData\Roaming\Python\Python310\site-packages\nornir\core\inventory.py", line 494, in get_connection
    self.open_connection(
  File "C:\Users\micha\AppData\Roaming\Python\Python310\site-packages\nornir\core\inventory.py", line 546, in open_connection
    conn_obj.open(
  File "C:\Users\micha\AppData\Roaming\Python\Python310\site-packages\nornir_napalm\plugins\connections\__init__.py", line 57, in open
    connection.open()
  File "C:\Users\micha\AppData\Roaming\Python\Python310\site-packages\napalm\ios\ios.py", line 169, in open
    self.device = self._netmiko_open(
  File "C:\Users\micha\AppData\Roaming\Python\Python310\site-packages\napalm\base\base.py", line 86, in _netmiko_open
    self._netmiko_device = ConnectHandler(
  File "C:\Users\micha\AppData\Roaming\Python\Python310\site-packages\netmiko\ssh_dispatcher.py", line 326, in ConnectHandler
    return ConnectionClass(*args, **kwargs)
  File "C:\Users\micha\AppData\Roaming\Python\Python310\site-packages\netmiko\cisco\cisco_ios.py", line 17, in __init__
    return super().__init__(*args, **kwargs)
  File "C:\Users\micha\AppData\Roaming\Python\Python310\site-packages\netmiko\base_connection.py", line 350, in __init__
    self._open()
  File "C:\Users\micha\AppData\Roaming\Python\Python310\site-packages\netmiko\base_connection.py", line 355, in _open
    self.establish_connection()
  File "C:\Users\micha\AppData\Roaming\Python\Python310\site-packages\netmiko\base_connection.py", line 935, in establish_connection
    self.remote_conn_pre.connect(**ssh_connect_params)
  File "C:\Users\micha\AppData\Roaming\Python\Python310\site-packages\paramiko\client.py", line 406, in connect
    t.start_client(timeout=timeout)
  File "C:\Users\micha\AppData\Roaming\Python\Python310\site-packages\paramiko\transport.py", line 660, in start_client
    raise e
  File "C:\Users\micha\AppData\Roaming\Python\Python310\site-packages\paramiko\transport.py", line 2039, in run
    self._check_banner()
  File "C:\Users\micha\AppData\Roaming\Python\Python310\site-packages\paramiko\transport.py", line 2215, in _check_banner
    raise SSHException(
paramiko.ssh_exception.SSHException: Error reading SSH protocol banner'utf-8' codec can't decode byte 0xff in position 0: invalid start byte

2022-02-17 17:59:55,533 - nornir.core.task -    ERROR -      start() - Host 'host1': task 'Backup Device configurations' failed with traceback:
Traceback (most recent call last):
  File "C:\Users\micha\AppData\Roaming\Python\Python310\site-packages\nornir\core\task.py", line 99, in start
    r = self.task(self, **self.params)
  File "c:\Users\micha\OneDrive\Documents\Code Repo\nornir\nornir_test.py", line 16, in backup_config
    device_config = task.run(task=napalm_get, getters=["get_config"])
  File "C:\Users\micha\AppData\Roaming\Python\Python310\site-packages\nornir\core\task.py", line 174, in run
    raise NornirSubTaskError(task=run_task, result=r)
nornir.core.exceptions.NornirSubTaskError: Subtask: napalm_get (failed)


2022-02-22 14:57:41,354 -  nornir.core -     INFO -        run() - Running task 'Backup Device configurations' with args {'path': './data/configs'} on 1 hosts
2022-02-22 14:57:43,295 - nornir.core.task -    ERROR -      start() - Host 'host1': task 'Backup Device configurations' failed with traceback:
Traceback (most recent call last):
  File "C:\Users\micha\AppData\Roaming\Python\Python310\site-packages\nornir\core\task.py", line 99, in start
    r = self.task(self, **self.params)
  File "c:\Users\micha\OneDrive\Documents\Code Repo\nornir\nornir_test.py", line 21, in backup_config
    content=device_config.result["config"]["running"],
KeyError: 'config'

2022-02-22 15:01:38,610 -  nornir.core -     INFO -        run() - Running task 'Backup Device configurations' with args {'path': './data/configs'} on 1 hosts
2022-02-22 15:03:21,561 -  nornir.core -     INFO -        run() - Running task 'Backup Device configurations' with args {'path': './data/configs'} on 1 hosts
2022-02-22 15:03:23,435 - nornir.core.task -    ERROR -      start() - Host 'host1': task 'write_file' failed with traceback:
Traceback (most recent call last):
  File "C:\Users\micha\AppData\Roaming\Python\Python310\site-packages\nornir\core\task.py", line 99, in start
    r = self.task(self, **self.params)
  File "C:\Users\micha\AppData\Roaming\Python\Python310\site-packages\nornir_utils\plugins\tasks\files\write_file.py", line 51, in write_file
    diff = _generate_diff(filename, content, append)
  File "C:\Users\micha\AppData\Roaming\Python\Python310\site-packages\nornir_utils\plugins\tasks\files\write_file.py", line 23, in _generate_diff
    new_content = content.splitlines()
AttributeError: 'dict' object has no attribute 'splitlines'

2022-02-22 15:03:23,435 - nornir.core.task -    ERROR -      start() - Host 'host1': task 'Backup Device configurations' failed with traceback:
Traceback (most recent call last):
  File "C:\Users\micha\AppData\Roaming\Python\Python310\site-packages\nornir\core\task.py", line 99, in start
    r = self.task(self, **self.params)
  File "c:\Users\micha\OneDrive\Documents\Code Repo\nornir\nornir_test.py", line 19, in backup_config
    task.run(
  File "C:\Users\micha\AppData\Roaming\Python\Python310\site-packages\nornir\core\task.py", line 174, in run
    raise NornirSubTaskError(task=run_task, result=r)
nornir.core.exceptions.NornirSubTaskError: Subtask: write_file (failed)


2022-02-22 15:07:36,560 -  nornir.core -     INFO -        run() - Running task 'Backup Device configurations' with args {'path': './data/configs'} on 1 hosts
2022-02-22 15:07:38,316 - nornir.core.task -    ERROR -      start() - Host 'host1': task 'Backup Device configurations' failed with traceback:
Traceback (most recent call last):
  File "C:\Users\micha\AppData\Roaming\Python\Python310\site-packages\nornir\core\task.py", line 99, in start
    r = self.task(self, **self.params)
  File "c:\Users\micha\OneDrive\Documents\Code Repo\nornir\nornir_test.py", line 21, in backup_config
    content=device_config.result["running"],
KeyError: 'running'

2022-02-22 15:09:46,550 -  nornir.core -     INFO -        run() - Running task 'Backup Device configurations' with args {'path': './data/configs'} on 1 hosts
2022-02-22 15:09:48,569 - nornir.core.task -    ERROR -      start() - Host 'host1': task 'Backup Device configurations' failed with traceback:
Traceback (most recent call last):
  File "C:\Users\micha\AppData\Roaming\Python\Python310\site-packages\nornir\core\task.py", line 99, in start
    r = self.task(self, **self.params)
  File "c:\Users\micha\OneDrive\Documents\Code Repo\nornir\nornir_test.py", line 21, in backup_config
    content=device_config.result['config']["running"],
KeyError: 'config'

2022-02-22 15:10:39,325 -  nornir.core -     INFO -        run() - Running task 'Backup Device configurations' with args {'path': './data/configs'} on 1 hosts
2022-02-22 15:10:41,174 - nornir.core.task -    ERROR -      start() - Host 'host1': task 'write_file' failed with traceback:
Traceback (most recent call last):
  File "C:\Users\micha\AppData\Roaming\Python\Python310\site-packages\nornir\core\task.py", line 99, in start
    r = self.task(self, **self.params)
  File "C:\Users\micha\AppData\Roaming\Python\Python310\site-packages\nornir_utils\plugins\tasks\files\write_file.py", line 51, in write_file
    diff = _generate_diff(filename, content, append)
  File "C:\Users\micha\AppData\Roaming\Python\Python310\site-packages\nornir_utils\plugins\tasks\files\write_file.py", line 23, in _generate_diff
    new_content = content.splitlines()
AttributeError: 'dict' object has no attribute 'splitlines'

2022-02-22 15:10:41,174 - nornir.core.task -    ERROR -      start() - Host 'host1': task 'Backup Device configurations' failed with traceback:
Traceback (most recent call last):
  File "C:\Users\micha\AppData\Roaming\Python\Python310\site-packages\nornir\core\task.py", line 99, in start
    r = self.task(self, **self.params)
  File "c:\Users\micha\OneDrive\Documents\Code Repo\nornir\nornir_test.py", line 19, in backup_config
    task.run(
  File "C:\Users\micha\AppData\Roaming\Python\Python310\site-packages\nornir\core\task.py", line 174, in run
    raise NornirSubTaskError(task=run_task, result=r)
nornir.core.exceptions.NornirSubTaskError: Subtask: write_file (failed)


2022-02-22 15:12:24,368 -  nornir.core -     INFO -        run() - Running task 'Backup Device configurations' with args {'path': './data/configs'} on 1 hosts
2022-02-22 15:12:26,184 - nornir.core.task -    ERROR -      start() - Host 'host1': task 'Backup Device configurations' failed with traceback:
Traceback (most recent call last):
  File "C:\Users\micha\AppData\Roaming\Python\Python310\site-packages\nornir\core\task.py", line 99, in start
    r = self.task(self, **self.params)
  File "c:\Users\micha\OneDrive\Documents\Code Repo\nornir\nornir_test.py", line 22, in backup_config
    content=device_config.result['config']["running"],
KeyError: 'config'

2022-02-22 15:13:40,502 -  nornir.core -     INFO -        run() - Running task 'Backup Device configurations' with args {'path': './data/configs'} on 1 hosts
2022-02-22 15:13:42,264 - nornir.core.task -    ERROR -      start() - Host 'host1': task 'Backup Device configurations' failed with traceback:
Traceback (most recent call last):
  File "C:\Users\micha\AppData\Roaming\Python\Python310\site-packages\nornir\core\task.py", line 99, in start
    r = self.task(self, **self.params)
  File "c:\Users\micha\OneDrive\Documents\Code Repo\nornir\nornir_test.py", line 21, in backup_config
    content=device_config.result['config']["running"],
KeyError: 'config'

2022-02-22 15:13:56,430 -  nornir.core -     INFO -        run() - Running task 'Backup Device configurations' with args {'path': './data/configs'} on 1 hosts
2022-02-22 15:13:58,143 - nornir.core.task -    ERROR -      start() - Host 'host1': task 'Backup Device configurations' failed with traceback:
Traceback (most recent call last):
  File "C:\Users\micha\AppData\Roaming\Python\Python310\site-packages\nornir\core\task.py", line 99, in start
    r = self.task(self, **self.params)
  File "c:\Users\micha\OneDrive\Documents\Code Repo\nornir\nornir_test.py", line 21, in backup_config
    content=device_config.result['config']["running"],
KeyError: 'config'

2022-02-22 15:14:02,966 -  nornir.core -     INFO -        run() - Running task 'Backup Device configurations' with args {'path': './data/configs'} on 1 hosts
2022-02-22 15:14:04,771 - nornir.core.task -    ERROR -      start() - Host 'host1': task 'Backup Device configurations' failed with traceback:
Traceback (most recent call last):
  File "C:\Users\micha\AppData\Roaming\Python\Python310\site-packages\nornir\core\task.py", line 99, in start
    r = self.task(self, **self.params)
  File "c:\Users\micha\OneDrive\Documents\Code Repo\nornir\nornir_test.py", line 21, in backup_config
    content=device_config.result['config']["running"],
KeyError: 'config'

2022-02-22 15:18:07,735 -  nornir.core -     INFO -        run() - Running task 'Backup Device configurations' with args {'path': './data/configs'} on 1 hosts
2022-02-22 15:18:09,675 - nornir.core.task -    ERROR -      start() - Host 'host1': task 'write_file' failed with traceback:
Traceback (most recent call last):
  File "C:\Users\micha\AppData\Roaming\Python\Python310\site-packages\nornir\core\task.py", line 99, in start
    r = self.task(self, **self.params)
  File "C:\Users\micha\AppData\Roaming\Python\Python310\site-packages\nornir_utils\plugins\tasks\files\write_file.py", line 55, in write_file
    with open(filename, mode=mode) as f:
FileNotFoundError: [Errno 2] No such file or directory: './data/configs/host1.txt'

2022-02-22 15:18:09,676 - nornir.core.task -    ERROR -      start() - Host 'host1': task 'Backup Device configurations' failed with traceback:
Traceback (most recent call last):
  File "C:\Users\micha\AppData\Roaming\Python\Python310\site-packages\nornir\core\task.py", line 99, in start
    r = self.task(self, **self.params)
  File "c:\Users\micha\OneDrive\Documents\Code Repo\nornir\nornir_test.py", line 19, in backup_config
    task.run(
  File "C:\Users\micha\AppData\Roaming\Python\Python310\site-packages\nornir\core\task.py", line 174, in run
    raise NornirSubTaskError(task=run_task, result=r)
nornir.core.exceptions.NornirSubTaskError: Subtask: write_file (failed)


2022-02-22 15:19:01,266 -  nornir.core -     INFO -        run() - Running task 'Backup Device configurations' with args {'path': './data/configs'} on 1 hosts
2022-02-22 15:19:03,152 - nornir.core.task -    ERROR -      start() - Host 'host1': task 'write_file' failed with traceback:
Traceback (most recent call last):
  File "C:\Users\micha\AppData\Roaming\Python\Python310\site-packages\nornir\core\task.py", line 99, in start
    r = self.task(self, **self.params)
  File "C:\Users\micha\AppData\Roaming\Python\Python310\site-packages\nornir_utils\plugins\tasks\files\write_file.py", line 55, in write_file
    with open(filename, mode=mode) as f:
FileNotFoundError: [Errno 2] No such file or directory: './data/configs/host1.txt'

2022-02-22 15:19:03,153 - nornir.core.task -    ERROR -      start() - Host 'host1': task 'Backup Device configurations' failed with traceback:
Traceback (most recent call last):
  File "C:\Users\micha\AppData\Roaming\Python\Python310\site-packages\nornir\core\task.py", line 99, in start
    r = self.task(self, **self.params)
  File "c:\Users\micha\OneDrive\Documents\Code Repo\nornir\nornir_test.py", line 19, in backup_config
    task.run(
  File "C:\Users\micha\AppData\Roaming\Python\Python310\site-packages\nornir\core\task.py", line 174, in run
    raise NornirSubTaskError(task=run_task, result=r)
nornir.core.exceptions.NornirSubTaskError: Subtask: write_file (failed)


2022-02-22 15:25:23,127 -  nornir.core -     INFO -        run() - Running task 'Backup Device configurations' with args {'path': './data/configs'} on 1 hosts
2022-02-22 15:27:57,279 -  nornir.core -     INFO -        run() - Running task 'Backup Device configurations' with args {'path': './data/configs'} on 1 hosts
2022-02-22 15:28:45,383 -  nornir.core -     INFO -        run() - Running task 'Backup Device configurations' with args {'path': './data/configs'} on 1 hosts
2022-02-22 15:29:51,328 -  nornir.core -     INFO -        run() - Running task 'Backup Device configurations' with args {'path': './data/configs'} on 1 hosts
2022-02-22 15:31:24,473 -  nornir.core -     INFO -        run() - Running task 'Backup Device configurations' with args {'path': './data/configs'} on 1 hosts
2022-02-22 15:31:47,322 -  nornir.core -     INFO -        run() - Running task 'Backup Device configurations' with args {'path': './data/configs'} on 1 hosts
2022-02-22 16:00:45,328 -  nornir.core -     INFO -        run() - Running task 'Backup Device configurations' with args {'path': './data/configs'} on 2 hosts
2022-02-22 16:00:45,333 - nornir.core.task -    ERROR -      start() - Host 'CSR1000V-JCU-TEST3': task 'napalm_get' failed with traceback:
Traceback (most recent call last):
  File "C:\Users\micha\AppData\Roaming\Python\Python310\site-packages\nornir\core\task.py", line 99, in start
    r = self.task(self, **self.params)
  File "C:\Users\micha\AppData\Roaming\Python\Python310\site-packages\nornir_napalm\plugins\tasks\napalm_get.py", line 32, in napalm_get
    device = task.host.get_connection(CONNECTION_NAME, task.nornir.config)
  File "C:\Users\micha\AppData\Roaming\Python\Python310\site-packages\nornir\core\inventory.py", line 494, in get_connection
    self.open_connection(
  File "C:\Users\micha\AppData\Roaming\Python\Python310\site-packages\nornir\core\inventory.py", line 546, in open_connection
    conn_obj.open(
  File "C:\Users\micha\AppData\Roaming\Python\Python310\site-packages\nornir_napalm\plugins\connections\__init__.py", line 55, in open
    network_driver = get_network_driver(platform)
  File "C:\Users\micha\AppData\Roaming\Python\Python310\site-packages\napalm\base\__init__.py", line 97, in get_network_driver
    raise ModuleImportError(
napalm.base.exceptions.ModuleImportError: Cannot import "nts". Is the library installed?

2022-02-22 16:00:45,333 - nornir.core.task -    ERROR -      start() - Host 'CSR1000V-JCU-TEST4': task 'napalm_get' failed with traceback:
Traceback (most recent call last):
  File "C:\Users\micha\AppData\Roaming\Python\Python310\site-packages\nornir\core\task.py", line 99, in start
    r = self.task(self, **self.params)
  File "C:\Users\micha\AppData\Roaming\Python\Python310\site-packages\nornir_napalm\plugins\tasks\napalm_get.py", line 32, in napalm_get
    device = task.host.get_connection(CONNECTION_NAME, task.nornir.config)
  File "C:\Users\micha\AppData\Roaming\Python\Python310\site-packages\nornir\core\inventory.py", line 494, in get_connection
    self.open_connection(
  File "C:\Users\micha\AppData\Roaming\Python\Python310\site-packages\nornir\core\inventory.py", line 546, in open_connection
    conn_obj.open(
  File "C:\Users\micha\AppData\Roaming\Python\Python310\site-packages\nornir_napalm\plugins\connections\__init__.py", line 55, in open
    network_driver = get_network_driver(platform)
  File "C:\Users\micha\AppData\Roaming\Python\Python310\site-packages\napalm\base\__init__.py", line 97, in get_network_driver
    raise ModuleImportError(
napalm.base.exceptions.ModuleImportError: Cannot import "nts". Is the library installed?

2022-02-22 16:00:45,333 - nornir.core.task -    ERROR -      start() - Host 'CSR1000V-JCU-TEST3': task 'Backup Device configurations' failed with traceback:
Traceback (most recent call last):
  File "C:\Users\micha\AppData\Roaming\Python\Python310\site-packages\nornir\core\task.py", line 99, in start
    r = self.task(self, **self.params)
  File "c:\Users\micha\OneDrive\Documents\Code Repo\nornir\source\nornir_test.py", line 17, in backup_config
    device_config = task.run(task=napalm_get, getters=["config"])
  File "C:\Users\micha\AppData\Roaming\Python\Python310\site-packages\nornir\core\task.py", line 174, in run
    raise NornirSubTaskError(task=run_task, result=r)
nornir.core.exceptions.NornirSubTaskError: Subtask: napalm_get (failed)


2022-02-22 16:00:45,334 - nornir.core.task -    ERROR -      start() - Host 'CSR1000V-JCU-TEST4': task 'Backup Device configurations' failed with traceback:
Traceback (most recent call last):
  File "C:\Users\micha\AppData\Roaming\Python\Python310\site-packages\nornir\core\task.py", line 99, in start
    r = self.task(self, **self.params)
  File "c:\Users\micha\OneDrive\Documents\Code Repo\nornir\source\nornir_test.py", line 17, in backup_config
    device_config = task.run(task=napalm_get, getters=["config"])
  File "C:\Users\micha\AppData\Roaming\Python\Python310\site-packages\nornir\core\task.py", line 174, in run
    raise NornirSubTaskError(task=run_task, result=r)
nornir.core.exceptions.NornirSubTaskError: Subtask: napalm_get (failed)


2022-02-22 16:00:57,218 -  nornir.core -     INFO -        run() - Running task 'Backup Device configurations' with args {'path': './data/configs'} on 2 hosts
2022-02-22 16:00:57,221 - nornir.core.task -    ERROR -      start() - Host 'CSR1000V-JCU-TEST3': task 'napalm_get' failed with traceback:
Traceback (most recent call last):
  File "C:\Users\micha\AppData\Roaming\Python\Python310\site-packages\nornir\core\task.py", line 99, in start
    r = self.task(self, **self.params)
  File "C:\Users\micha\AppData\Roaming\Python\Python310\site-packages\nornir_napalm\plugins\tasks\napalm_get.py", line 32, in napalm_get
    device = task.host.get_connection(CONNECTION_NAME, task.nornir.config)
  File "C:\Users\micha\AppData\Roaming\Python\Python310\site-packages\nornir\core\inventory.py", line 494, in get_connection
    self.open_connection(
  File "C:\Users\micha\AppData\Roaming\Python\Python310\site-packages\nornir\core\inventory.py", line 546, in open_connection
    conn_obj.open(
  File "C:\Users\micha\AppData\Roaming\Python\Python310\site-packages\nornir_napalm\plugins\connections\__init__.py", line 55, in open
    network_driver = get_network_driver(platform)
  File "C:\Users\micha\AppData\Roaming\Python\Python310\site-packages\napalm\base\__init__.py", line 97, in get_network_driver
    raise ModuleImportError(
napalm.base.exceptions.ModuleImportError: Cannot import "nts". Is the library installed?

2022-02-22 16:00:57,221 - nornir.core.task -    ERROR -      start() - Host 'CSR1000V-JCU-TEST4': task 'napalm_get' failed with traceback:
Traceback (most recent call last):
  File "C:\Users\micha\AppData\Roaming\Python\Python310\site-packages\nornir\core\task.py", line 99, in start
    r = self.task(self, **self.params)
  File "C:\Users\micha\AppData\Roaming\Python\Python310\site-packages\nornir_napalm\plugins\tasks\napalm_get.py", line 32, in napalm_get
    device = task.host.get_connection(CONNECTION_NAME, task.nornir.config)
  File "C:\Users\micha\AppData\Roaming\Python\Python310\site-packages\nornir\core\inventory.py", line 494, in get_connection
    self.open_connection(
  File "C:\Users\micha\AppData\Roaming\Python\Python310\site-packages\nornir\core\inventory.py", line 546, in open_connection
    conn_obj.open(
  File "C:\Users\micha\AppData\Roaming\Python\Python310\site-packages\nornir_napalm\plugins\connections\__init__.py", line 55, in open
    network_driver = get_network_driver(platform)
  File "C:\Users\micha\AppData\Roaming\Python\Python310\site-packages\napalm\base\__init__.py", line 97, in get_network_driver
    raise ModuleImportError(
napalm.base.exceptions.ModuleImportError: Cannot import "nts". Is the library installed?

2022-02-22 16:00:57,222 - nornir.core.task -    ERROR -      start() - Host 'CSR1000V-JCU-TEST3': task 'Backup Device configurations' failed with traceback:
Traceback (most recent call last):
  File "C:\Users\micha\AppData\Roaming\Python\Python310\site-packages\nornir\core\task.py", line 99, in start
    r = self.task(self, **self.params)
  File "c:\Users\micha\OneDrive\Documents\Code Repo\nornir\source\nornir_test.py", line 17, in backup_config
    device_config = task.run(task=napalm_get, getters=["config"])
  File "C:\Users\micha\AppData\Roaming\Python\Python310\site-packages\nornir\core\task.py", line 174, in run
    raise NornirSubTaskError(task=run_task, result=r)
nornir.core.exceptions.NornirSubTaskError: Subtask: napalm_get (failed)


2022-02-22 16:00:57,222 - nornir.core.task -    ERROR -      start() - Host 'CSR1000V-JCU-TEST4': task 'Backup Device configurations' failed with traceback:
Traceback (most recent call last):
  File "C:\Users\micha\AppData\Roaming\Python\Python310\site-packages\nornir\core\task.py", line 99, in start
    r = self.task(self, **self.params)
  File "c:\Users\micha\OneDrive\Documents\Code Repo\nornir\source\nornir_test.py", line 17, in backup_config
    device_config = task.run(task=napalm_get, getters=["config"])
  File "C:\Users\micha\AppData\Roaming\Python\Python310\site-packages\nornir\core\task.py", line 174, in run
    raise NornirSubTaskError(task=run_task, result=r)
nornir.core.exceptions.NornirSubTaskError: Subtask: napalm_get (failed)


2022-02-22 16:03:08,649 -  nornir.core -     INFO -        run() - Running task 'Backup Device configurations' with args {'path': './data/configs'} on 2 hosts
2022-02-22 16:03:08,994 - nornir.core.task -    ERROR -      start() - Host 'CSR1000V-JCU-TEST4': task 'napalm_get' failed with traceback:
Traceback (most recent call last):
  File "C:\Users\micha\AppData\Roaming\Python\Python310\site-packages\nornir\core\task.py", line 99, in start
    r = self.task(self, **self.params)
  File "C:\Users\micha\AppData\Roaming\Python\Python310\site-packages\nornir_napalm\plugins\tasks\napalm_get.py", line 32, in napalm_get
    device = task.host.get_connection(CONNECTION_NAME, task.nornir.config)
  File "C:\Users\micha\AppData\Roaming\Python\Python310\site-packages\nornir\core\inventory.py", line 494, in get_connection
    self.open_connection(
  File "C:\Users\micha\AppData\Roaming\Python\Python310\site-packages\nornir\core\inventory.py", line 546, in open_connection
    conn_obj.open(
  File "C:\Users\micha\AppData\Roaming\Python\Python310\site-packages\nornir_napalm\plugins\connections\__init__.py", line 57, in open
    connection.open()
  File "C:\Users\micha\AppData\Roaming\Python\Python310\site-packages\napalm\ios\ios.py", line 169, in open
    self.device = self._netmiko_open(
  File "C:\Users\micha\AppData\Roaming\Python\Python310\site-packages\napalm\base\base.py", line 86, in _netmiko_open
    self._netmiko_device = ConnectHandler(
  File "C:\Users\micha\AppData\Roaming\Python\Python310\site-packages\netmiko\ssh_dispatcher.py", line 326, in ConnectHandler
    return ConnectionClass(*args, **kwargs)
  File "C:\Users\micha\AppData\Roaming\Python\Python310\site-packages\netmiko\cisco\cisco_ios.py", line 17, in __init__
    return super().__init__(*args, **kwargs)
  File "C:\Users\micha\AppData\Roaming\Python\Python310\site-packages\netmiko\base_connection.py", line 350, in __init__
    self._open()
  File "C:\Users\micha\AppData\Roaming\Python\Python310\site-packages\netmiko\base_connection.py", line 355, in _open
    self.establish_connection()
  File "C:\Users\micha\AppData\Roaming\Python\Python310\site-packages\netmiko\base_connection.py", line 935, in establish_connection
    self.remote_conn_pre.connect(**ssh_connect_params)
  File "C:\Users\micha\AppData\Roaming\Python\Python310\site-packages\paramiko\client.py", line 435, in connect
    self._auth(
  File "C:\Users\micha\AppData\Roaming\Python\Python310\site-packages\paramiko\client.py", line 765, in _auth
    raise SSHException("No authentication methods available")
paramiko.ssh_exception.SSHException: No authentication methods available

2022-02-22 16:03:08,995 - nornir.core.task -    ERROR -      start() - Host 'CSR1000V-JCU-TEST4': task 'Backup Device configurations' failed with traceback:
Traceback (most recent call last):
  File "C:\Users\micha\AppData\Roaming\Python\Python310\site-packages\nornir\core\task.py", line 99, in start
    r = self.task(self, **self.params)
  File "c:\Users\micha\OneDrive\Documents\Code Repo\nornir\source\nornir_test.py", line 17, in backup_config
    device_config = task.run(task=napalm_get, getters=["config"])
  File "C:\Users\micha\AppData\Roaming\Python\Python310\site-packages\nornir\core\task.py", line 174, in run
    raise NornirSubTaskError(task=run_task, result=r)
nornir.core.exceptions.NornirSubTaskError: Subtask: napalm_get (failed)


2022-02-22 16:03:09,255 - nornir.core.task -    ERROR -      start() - Host 'CSR1000V-JCU-TEST3': task 'napalm_get' failed with traceback:
Traceback (most recent call last):
  File "C:\Users\micha\AppData\Roaming\Python\Python310\site-packages\nornir\core\task.py", line 99, in start
    r = self.task(self, **self.params)
  File "C:\Users\micha\AppData\Roaming\Python\Python310\site-packages\nornir_napalm\plugins\tasks\napalm_get.py", line 32, in napalm_get
    device = task.host.get_connection(CONNECTION_NAME, task.nornir.config)
  File "C:\Users\micha\AppData\Roaming\Python\Python310\site-packages\nornir\core\inventory.py", line 494, in get_connection
    self.open_connection(
  File "C:\Users\micha\AppData\Roaming\Python\Python310\site-packages\nornir\core\inventory.py", line 546, in open_connection
    conn_obj.open(
  File "C:\Users\micha\AppData\Roaming\Python\Python310\site-packages\nornir_napalm\plugins\connections\__init__.py", line 57, in open
    connection.open()
  File "C:\Users\micha\AppData\Roaming\Python\Python310\site-packages\napalm\ios\ios.py", line 169, in open
    self.device = self._netmiko_open(
  File "C:\Users\micha\AppData\Roaming\Python\Python310\site-packages\napalm\base\base.py", line 86, in _netmiko_open
    self._netmiko_device = ConnectHandler(
  File "C:\Users\micha\AppData\Roaming\Python\Python310\site-packages\netmiko\ssh_dispatcher.py", line 326, in ConnectHandler
    return ConnectionClass(*args, **kwargs)
  File "C:\Users\micha\AppData\Roaming\Python\Python310\site-packages\netmiko\cisco\cisco_ios.py", line 17, in __init__
    return super().__init__(*args, **kwargs)
  File "C:\Users\micha\AppData\Roaming\Python\Python310\site-packages\netmiko\base_connection.py", line 350, in __init__
    self._open()
  File "C:\Users\micha\AppData\Roaming\Python\Python310\site-packages\netmiko\base_connection.py", line 355, in _open
    self.establish_connection()
  File "C:\Users\micha\AppData\Roaming\Python\Python310\site-packages\netmiko\base_connection.py", line 935, in establish_connection
    self.remote_conn_pre.connect(**ssh_connect_params)
  File "C:\Users\micha\AppData\Roaming\Python\Python310\site-packages\paramiko\client.py", line 435, in connect
    self._auth(
  File "C:\Users\micha\AppData\Roaming\Python\Python310\site-packages\paramiko\client.py", line 765, in _auth
    raise SSHException("No authentication methods available")
paramiko.ssh_exception.SSHException: No authentication methods available

2022-02-22 16:03:09,256 - nornir.core.task -    ERROR -      start() - Host 'CSR1000V-JCU-TEST3': task 'Backup Device configurations' failed with traceback:
Traceback (most recent call last):
  File "C:\Users\micha\AppData\Roaming\Python\Python310\site-packages\nornir\core\task.py", line 99, in start
    r = self.task(self, **self.params)
  File "c:\Users\micha\OneDrive\Documents\Code Repo\nornir\source\nornir_test.py", line 17, in backup_config
    device_config = task.run(task=napalm_get, getters=["config"])
  File "C:\Users\micha\AppData\Roaming\Python\Python310\site-packages\nornir\core\task.py", line 174, in run
    raise NornirSubTaskError(task=run_task, result=r)
nornir.core.exceptions.NornirSubTaskError: Subtask: napalm_get (failed)


2022-02-22 16:07:23,567 -  nornir.core -     INFO -        run() - Running task 'Backup Device configurations' with args {'path': './data/configs'} on 2 hosts
2022-02-22 16:07:23,999 - nornir.core.task -    ERROR -      start() - Host 'CSR1000V-JCU-TEST4': task 'napalm_get' failed with traceback:
Traceback (most recent call last):
  File "C:\Users\micha\AppData\Roaming\Python\Python310\site-packages\nornir\core\task.py", line 99, in start
    r = self.task(self, **self.params)
  File "C:\Users\micha\AppData\Roaming\Python\Python310\site-packages\nornir_napalm\plugins\tasks\napalm_get.py", line 32, in napalm_get
    device = task.host.get_connection(CONNECTION_NAME, task.nornir.config)
  File "C:\Users\micha\AppData\Roaming\Python\Python310\site-packages\nornir\core\inventory.py", line 494, in get_connection
    self.open_connection(
  File "C:\Users\micha\AppData\Roaming\Python\Python310\site-packages\nornir\core\inventory.py", line 546, in open_connection
    conn_obj.open(
  File "C:\Users\micha\AppData\Roaming\Python\Python310\site-packages\nornir_napalm\plugins\connections\__init__.py", line 57, in open
    connection.open()
  File "C:\Users\micha\AppData\Roaming\Python\Python310\site-packages\napalm\ios\ios.py", line 169, in open
    self.device = self._netmiko_open(
  File "C:\Users\micha\AppData\Roaming\Python\Python310\site-packages\napalm\base\base.py", line 86, in _netmiko_open
    self._netmiko_device = ConnectHandler(
  File "C:\Users\micha\AppData\Roaming\Python\Python310\site-packages\netmiko\ssh_dispatcher.py", line 326, in ConnectHandler
    return ConnectionClass(*args, **kwargs)
  File "C:\Users\micha\AppData\Roaming\Python\Python310\site-packages\netmiko\cisco\cisco_ios.py", line 17, in __init__
    return super().__init__(*args, **kwargs)
  File "C:\Users\micha\AppData\Roaming\Python\Python310\site-packages\netmiko\base_connection.py", line 350, in __init__
    self._open()
  File "C:\Users\micha\AppData\Roaming\Python\Python310\site-packages\netmiko\base_connection.py", line 355, in _open
    self.establish_connection()
  File "C:\Users\micha\AppData\Roaming\Python\Python310\site-packages\netmiko\base_connection.py", line 935, in establish_connection
    self.remote_conn_pre.connect(**ssh_connect_params)
  File "C:\Users\micha\AppData\Roaming\Python\Python310\site-packages\paramiko\client.py", line 435, in connect
    self._auth(
  File "C:\Users\micha\AppData\Roaming\Python\Python310\site-packages\paramiko\client.py", line 765, in _auth
    raise SSHException("No authentication methods available")
paramiko.ssh_exception.SSHException: No authentication methods available

2022-02-22 16:07:24,000 - nornir.core.task -    ERROR -      start() - Host 'CSR1000V-JCU-TEST4': task 'Backup Device configurations' failed with traceback:
Traceback (most recent call last):
  File "C:\Users\micha\AppData\Roaming\Python\Python310\site-packages\nornir\core\task.py", line 99, in start
    r = self.task(self, **self.params)
  File "c:\Users\micha\OneDrive\Documents\Code Repo\nornir\source\nornir_test.py", line 17, in backup_config
    device_config = task.run(task=napalm_get, getters=["config"])
  File "C:\Users\micha\AppData\Roaming\Python\Python310\site-packages\nornir\core\task.py", line 174, in run
    raise NornirSubTaskError(task=run_task, result=r)
nornir.core.exceptions.NornirSubTaskError: Subtask: napalm_get (failed)


2022-02-22 16:07:24,173 - nornir.core.task -    ERROR -      start() - Host 'CSR1000V-JCU-TEST3': task 'napalm_get' failed with traceback:
Traceback (most recent call last):
  File "C:\Users\micha\AppData\Roaming\Python\Python310\site-packages\nornir\core\task.py", line 99, in start
    r = self.task(self, **self.params)
  File "C:\Users\micha\AppData\Roaming\Python\Python310\site-packages\nornir_napalm\plugins\tasks\napalm_get.py", line 32, in napalm_get
    device = task.host.get_connection(CONNECTION_NAME, task.nornir.config)
  File "C:\Users\micha\AppData\Roaming\Python\Python310\site-packages\nornir\core\inventory.py", line 494, in get_connection
    self.open_connection(
  File "C:\Users\micha\AppData\Roaming\Python\Python310\site-packages\nornir\core\inventory.py", line 546, in open_connection
    conn_obj.open(
  File "C:\Users\micha\AppData\Roaming\Python\Python310\site-packages\nornir_napalm\plugins\connections\__init__.py", line 57, in open
    connection.open()
  File "C:\Users\micha\AppData\Roaming\Python\Python310\site-packages\napalm\ios\ios.py", line 169, in open
    self.device = self._netmiko_open(
  File "C:\Users\micha\AppData\Roaming\Python\Python310\site-packages\napalm\base\base.py", line 86, in _netmiko_open
    self._netmiko_device = ConnectHandler(
  File "C:\Users\micha\AppData\Roaming\Python\Python310\site-packages\netmiko\ssh_dispatcher.py", line 326, in ConnectHandler
    return ConnectionClass(*args, **kwargs)
  File "C:\Users\micha\AppData\Roaming\Python\Python310\site-packages\netmiko\cisco\cisco_ios.py", line 17, in __init__
    return super().__init__(*args, **kwargs)
  File "C:\Users\micha\AppData\Roaming\Python\Python310\site-packages\netmiko\base_connection.py", line 350, in __init__
    self._open()
  File "C:\Users\micha\AppData\Roaming\Python\Python310\site-packages\netmiko\base_connection.py", line 355, in _open
    self.establish_connection()
  File "C:\Users\micha\AppData\Roaming\Python\Python310\site-packages\netmiko\base_connection.py", line 935, in establish_connection
    self.remote_conn_pre.connect(**ssh_connect_params)
  File "C:\Users\micha\AppData\Roaming\Python\Python310\site-packages\paramiko\client.py", line 435, in connect
    self._auth(
  File "C:\Users\micha\AppData\Roaming\Python\Python310\site-packages\paramiko\client.py", line 765, in _auth
    raise SSHException("No authentication methods available")
paramiko.ssh_exception.SSHException: No authentication methods available

2022-02-22 16:07:24,173 - nornir.core.task -    ERROR -      start() - Host 'CSR1000V-JCU-TEST3': task 'Backup Device configurations' failed with traceback:
Traceback (most recent call last):
  File "C:\Users\micha\AppData\Roaming\Python\Python310\site-packages\nornir\core\task.py", line 99, in start
    r = self.task(self, **self.params)
  File "c:\Users\micha\OneDrive\Documents\Code Repo\nornir\source\nornir_test.py", line 17, in backup_config
    device_config = task.run(task=napalm_get, getters=["config"])
  File "C:\Users\micha\AppData\Roaming\Python\Python310\site-packages\nornir\core\task.py", line 174, in run
    raise NornirSubTaskError(task=run_task, result=r)
nornir.core.exceptions.NornirSubTaskError: Subtask: napalm_get (failed)


2022-02-22 16:17:08,359 -  nornir.core -     INFO -        run() - Running task 'Backup Device configurations' with args {'path': './data/configs'} on 2 hosts
2022-02-22 16:17:09,028 - nornir.core.task -    ERROR -      start() - Host 'CSR1000V-JCU-TEST4': task 'napalm_get' failed with traceback:
Traceback (most recent call last):
  File "C:\Users\micha\AppData\Roaming\Python\Python310\site-packages\nornir\core\task.py", line 99, in start
    r = self.task(self, **self.params)
  File "C:\Users\micha\AppData\Roaming\Python\Python310\site-packages\nornir_napalm\plugins\tasks\napalm_get.py", line 32, in napalm_get
    device = task.host.get_connection(CONNECTION_NAME, task.nornir.config)
  File "C:\Users\micha\AppData\Roaming\Python\Python310\site-packages\nornir\core\inventory.py", line 494, in get_connection
    self.open_connection(
  File "C:\Users\micha\AppData\Roaming\Python\Python310\site-packages\nornir\core\inventory.py", line 546, in open_connection
    conn_obj.open(
  File "C:\Users\micha\AppData\Roaming\Python\Python310\site-packages\nornir_napalm\plugins\connections\__init__.py", line 57, in open
    connection.open()
  File "C:\Users\micha\AppData\Roaming\Python\Python310\site-packages\napalm\ios\ios.py", line 169, in open
    self.device = self._netmiko_open(
  File "C:\Users\micha\AppData\Roaming\Python\Python310\site-packages\napalm\base\base.py", line 86, in _netmiko_open
    self._netmiko_device = ConnectHandler(
  File "C:\Users\micha\AppData\Roaming\Python\Python310\site-packages\netmiko\ssh_dispatcher.py", line 326, in ConnectHandler
    return ConnectionClass(*args, **kwargs)
  File "C:\Users\micha\AppData\Roaming\Python\Python310\site-packages\netmiko\cisco\cisco_ios.py", line 17, in __init__
    return super().__init__(*args, **kwargs)
  File "C:\Users\micha\AppData\Roaming\Python\Python310\site-packages\netmiko\base_connection.py", line 350, in __init__
    self._open()
  File "C:\Users\micha\AppData\Roaming\Python\Python310\site-packages\netmiko\base_connection.py", line 355, in _open
    self.establish_connection()
  File "C:\Users\micha\AppData\Roaming\Python\Python310\site-packages\netmiko\base_connection.py", line 935, in establish_connection
    self.remote_conn_pre.connect(**ssh_connect_params)
  File "C:\Users\micha\AppData\Roaming\Python\Python310\site-packages\paramiko\client.py", line 435, in connect
    self._auth(
  File "C:\Users\micha\AppData\Roaming\Python\Python310\site-packages\paramiko\client.py", line 765, in _auth
    raise SSHException("No authentication methods available")
paramiko.ssh_exception.SSHException: No authentication methods available

2022-02-22 16:17:09,028 - nornir.core.task -    ERROR -      start() - Host 'CSR1000V-JCU-TEST4': task 'Backup Device configurations' failed with traceback:
Traceback (most recent call last):
  File "C:\Users\micha\AppData\Roaming\Python\Python310\site-packages\nornir\core\task.py", line 99, in start
    r = self.task(self, **self.params)
  File "c:\Users\micha\OneDrive\Documents\Code Repo\nornir\source\nornir_test.py", line 17, in backup_config
    device_config = task.run(task=napalm_get, getters=["config"])
  File "C:\Users\micha\AppData\Roaming\Python\Python310\site-packages\nornir\core\task.py", line 174, in run
    raise NornirSubTaskError(task=run_task, result=r)
nornir.core.exceptions.NornirSubTaskError: Subtask: napalm_get (failed)


2022-02-22 16:17:09,226 - nornir.core.task -    ERROR -      start() - Host 'CSR1000V-JCU-TEST3': task 'napalm_get' failed with traceback:
Traceback (most recent call last):
  File "C:\Users\micha\AppData\Roaming\Python\Python310\site-packages\nornir\core\task.py", line 99, in start
    r = self.task(self, **self.params)
  File "C:\Users\micha\AppData\Roaming\Python\Python310\site-packages\nornir_napalm\plugins\tasks\napalm_get.py", line 32, in napalm_get
    device = task.host.get_connection(CONNECTION_NAME, task.nornir.config)
  File "C:\Users\micha\AppData\Roaming\Python\Python310\site-packages\nornir\core\inventory.py", line 494, in get_connection
    self.open_connection(
  File "C:\Users\micha\AppData\Roaming\Python\Python310\site-packages\nornir\core\inventory.py", line 546, in open_connection
    conn_obj.open(
  File "C:\Users\micha\AppData\Roaming\Python\Python310\site-packages\nornir_napalm\plugins\connections\__init__.py", line 57, in open
    connection.open()
  File "C:\Users\micha\AppData\Roaming\Python\Python310\site-packages\napalm\ios\ios.py", line 169, in open
    self.device = self._netmiko_open(
  File "C:\Users\micha\AppData\Roaming\Python\Python310\site-packages\napalm\base\base.py", line 86, in _netmiko_open
    self._netmiko_device = ConnectHandler(
  File "C:\Users\micha\AppData\Roaming\Python\Python310\site-packages\netmiko\ssh_dispatcher.py", line 326, in ConnectHandler
    return ConnectionClass(*args, **kwargs)
  File "C:\Users\micha\AppData\Roaming\Python\Python310\site-packages\netmiko\cisco\cisco_ios.py", line 17, in __init__
    return super().__init__(*args, **kwargs)
  File "C:\Users\micha\AppData\Roaming\Python\Python310\site-packages\netmiko\base_connection.py", line 350, in __init__
    self._open()
  File "C:\Users\micha\AppData\Roaming\Python\Python310\site-packages\netmiko\base_connection.py", line 355, in _open
    self.establish_connection()
  File "C:\Users\micha\AppData\Roaming\Python\Python310\site-packages\netmiko\base_connection.py", line 935, in establish_connection
    self.remote_conn_pre.connect(**ssh_connect_params)
  File "C:\Users\micha\AppData\Roaming\Python\Python310\site-packages\paramiko\client.py", line 435, in connect
    self._auth(
  File "C:\Users\micha\AppData\Roaming\Python\Python310\site-packages\paramiko\client.py", line 765, in _auth
    raise SSHException("No authentication methods available")
paramiko.ssh_exception.SSHException: No authentication methods available

2022-02-22 16:17:09,226 - nornir.core.task -    ERROR -      start() - Host 'CSR1000V-JCU-TEST3': task 'Backup Device configurations' failed with traceback:
Traceback (most recent call last):
  File "C:\Users\micha\AppData\Roaming\Python\Python310\site-packages\nornir\core\task.py", line 99, in start
    r = self.task(self, **self.params)
  File "c:\Users\micha\OneDrive\Documents\Code Repo\nornir\source\nornir_test.py", line 17, in backup_config
    device_config = task.run(task=napalm_get, getters=["config"])
  File "C:\Users\micha\AppData\Roaming\Python\Python310\site-packages\nornir\core\task.py", line 174, in run
    raise NornirSubTaskError(task=run_task, result=r)
nornir.core.exceptions.NornirSubTaskError: Subtask: napalm_get (failed)


2022-02-22 16:29:00,657 -  nornir.core -     INFO -        run() - Running task 'Backup Device configurations' with args {'path': './data/configs'} on 2 hosts
2022-02-22 16:29:01,097 - nornir.core.task -    ERROR -      start() - Host 'CSR1000V-JCU-TEST4': task 'napalm_get' failed with traceback:
Traceback (most recent call last):
  File "C:\Users\micha\AppData\Roaming\Python\Python310\site-packages\nornir\core\task.py", line 99, in start
    r = self.task(self, **self.params)
  File "C:\Users\micha\AppData\Roaming\Python\Python310\site-packages\nornir_napalm\plugins\tasks\napalm_get.py", line 32, in napalm_get
    device = task.host.get_connection(CONNECTION_NAME, task.nornir.config)
  File "C:\Users\micha\AppData\Roaming\Python\Python310\site-packages\nornir\core\inventory.py", line 494, in get_connection
    self.open_connection(
  File "C:\Users\micha\AppData\Roaming\Python\Python310\site-packages\nornir\core\inventory.py", line 546, in open_connection
    conn_obj.open(
  File "C:\Users\micha\AppData\Roaming\Python\Python310\site-packages\nornir_napalm\plugins\connections\__init__.py", line 57, in open
    connection.open()
  File "C:\Users\micha\AppData\Roaming\Python\Python310\site-packages\napalm\ios\ios.py", line 169, in open
    self.device = self._netmiko_open(
  File "C:\Users\micha\AppData\Roaming\Python\Python310\site-packages\napalm\base\base.py", line 86, in _netmiko_open
    self._netmiko_device = ConnectHandler(
  File "C:\Users\micha\AppData\Roaming\Python\Python310\site-packages\netmiko\ssh_dispatcher.py", line 326, in ConnectHandler
    return ConnectionClass(*args, **kwargs)
  File "C:\Users\micha\AppData\Roaming\Python\Python310\site-packages\netmiko\cisco\cisco_ios.py", line 17, in __init__
    return super().__init__(*args, **kwargs)
  File "C:\Users\micha\AppData\Roaming\Python\Python310\site-packages\netmiko\base_connection.py", line 350, in __init__
    self._open()
  File "C:\Users\micha\AppData\Roaming\Python\Python310\site-packages\netmiko\base_connection.py", line 355, in _open
    self.establish_connection()
  File "C:\Users\micha\AppData\Roaming\Python\Python310\site-packages\netmiko\base_connection.py", line 935, in establish_connection
    self.remote_conn_pre.connect(**ssh_connect_params)
  File "C:\Users\micha\AppData\Roaming\Python\Python310\site-packages\paramiko\client.py", line 435, in connect
    self._auth(
  File "C:\Users\micha\AppData\Roaming\Python\Python310\site-packages\paramiko\client.py", line 765, in _auth
    raise SSHException("No authentication methods available")
paramiko.ssh_exception.SSHException: No authentication methods available

2022-02-22 16:29:01,098 - nornir.core.task -    ERROR -      start() - Host 'CSR1000V-JCU-TEST4': task 'Backup Device configurations' failed with traceback:
Traceback (most recent call last):
  File "C:\Users\micha\AppData\Roaming\Python\Python310\site-packages\nornir\core\task.py", line 99, in start
    r = self.task(self, **self.params)
  File "c:\Users\micha\OneDrive\Documents\Code Repo\nornir\source\nornir_test.py", line 17, in backup_config
    device_config = task.run(task=napalm_get, getters=["config"])
  File "C:\Users\micha\AppData\Roaming\Python\Python310\site-packages\nornir\core\task.py", line 174, in run
    raise NornirSubTaskError(task=run_task, result=r)
nornir.core.exceptions.NornirSubTaskError: Subtask: napalm_get (failed)


2022-02-22 16:29:01,282 - nornir.core.task -    ERROR -      start() - Host 'CSR1000V-JCU-TEST3': task 'napalm_get' failed with traceback:
Traceback (most recent call last):
  File "C:\Users\micha\AppData\Roaming\Python\Python310\site-packages\nornir\core\task.py", line 99, in start
    r = self.task(self, **self.params)
  File "C:\Users\micha\AppData\Roaming\Python\Python310\site-packages\nornir_napalm\plugins\tasks\napalm_get.py", line 32, in napalm_get
    device = task.host.get_connection(CONNECTION_NAME, task.nornir.config)
  File "C:\Users\micha\AppData\Roaming\Python\Python310\site-packages\nornir\core\inventory.py", line 494, in get_connection
    self.open_connection(
  File "C:\Users\micha\AppData\Roaming\Python\Python310\site-packages\nornir\core\inventory.py", line 546, in open_connection
    conn_obj.open(
  File "C:\Users\micha\AppData\Roaming\Python\Python310\site-packages\nornir_napalm\plugins\connections\__init__.py", line 57, in open
    connection.open()
  File "C:\Users\micha\AppData\Roaming\Python\Python310\site-packages\napalm\ios\ios.py", line 169, in open
    self.device = self._netmiko_open(
  File "C:\Users\micha\AppData\Roaming\Python\Python310\site-packages\napalm\base\base.py", line 86, in _netmiko_open
    self._netmiko_device = ConnectHandler(
  File "C:\Users\micha\AppData\Roaming\Python\Python310\site-packages\netmiko\ssh_dispatcher.py", line 326, in ConnectHandler
    return ConnectionClass(*args, **kwargs)
  File "C:\Users\micha\AppData\Roaming\Python\Python310\site-packages\netmiko\cisco\cisco_ios.py", line 17, in __init__
    return super().__init__(*args, **kwargs)
  File "C:\Users\micha\AppData\Roaming\Python\Python310\site-packages\netmiko\base_connection.py", line 350, in __init__
    self._open()
  File "C:\Users\micha\AppData\Roaming\Python\Python310\site-packages\netmiko\base_connection.py", line 355, in _open
    self.establish_connection()
  File "C:\Users\micha\AppData\Roaming\Python\Python310\site-packages\netmiko\base_connection.py", line 935, in establish_connection
    self.remote_conn_pre.connect(**ssh_connect_params)
  File "C:\Users\micha\AppData\Roaming\Python\Python310\site-packages\paramiko\client.py", line 435, in connect
    self._auth(
  File "C:\Users\micha\AppData\Roaming\Python\Python310\site-packages\paramiko\client.py", line 765, in _auth
    raise SSHException("No authentication methods available")
paramiko.ssh_exception.SSHException: No authentication methods available

2022-02-22 16:29:01,283 - nornir.core.task -    ERROR -      start() - Host 'CSR1000V-JCU-TEST3': task 'Backup Device configurations' failed with traceback:
Traceback (most recent call last):
  File "C:\Users\micha\AppData\Roaming\Python\Python310\site-packages\nornir\core\task.py", line 99, in start
    r = self.task(self, **self.params)
  File "c:\Users\micha\OneDrive\Documents\Code Repo\nornir\source\nornir_test.py", line 17, in backup_config
    device_config = task.run(task=napalm_get, getters=["config"])
  File "C:\Users\micha\AppData\Roaming\Python\Python310\site-packages\nornir\core\task.py", line 174, in run
    raise NornirSubTaskError(task=run_task, result=r)
nornir.core.exceptions.NornirSubTaskError: Subtask: napalm_get (failed)


2022-02-22 22:37:13,782 -  nornir.core -     INFO -        run() - Running task 'Backup Device configurations' with args {'path': './data/configs'} on 2 hosts
